Workbook

Sheet Simulations
A1: Burn | B1: 0.25 | C1: Total | D1: 15000000 | E1: volume-weighted token distribution
B2: Year | C2: APY | E2: 0.25 | G2: 0.5 | I2: 0.6 | K2: 0.8 | M2: 1 | P2: Volume-weighted distribution
E3: Distributed | F3: Burned | G3: Distributed | H3: Burned | I3: Distributed | J3: Burned | K3: Distributed | L3: Burned | M3: Distributed | N3: Burned | P3: Volume | Q3: % Distribution
B4: 1 | C4: 0.08 | E4: {=INDIRECT("'Year "&$B4&"'"&"!P5")} -> 295233.98 | F4: {=INDIRECT("'Year "&$B4&"'"&"!P6")} -> 221425.49 | G4: {=INDIRECT("'Year "&$B4&"'"&"!ae5")} -> 586439.19 | H4: {=INDIRECT("'Year "&$B4&"'"&"!ae6")} -> 146609.8 | I4: {=INDIRECT("'Year "&$B4&"'"&"!at5")} -> 701804.47 | J4: {=INDIRECT("'Year "&$B4&"'"&"!at6")} -> 116967.41 | K4: {=INDIRECT("'Year "&$B4&"'"&"!bi5")} -> 930638.01 | L4: {=INDIRECT("'Year "&$B4&"'"&"!bi6")} -> 58164.876 | M4: {=INDIRECT("'Year "&$B4&"'"&"!bx5")} -> 1156963.3 | N4: {=INDIRECT("'Year "&$B4&"'"&"!bx6")} -> 0 | P4: <= $50M | Q4: 0.25
B5: 2 | C5: 0.08 | E5: {=INDIRECT("'Year "&$B5&"'"&"!P5")} -> 285064.95 | F5: {=INDIRECT("'Year "&$B5&"'"&"!P6")} -> 213798.72 | G5: {=INDIRECT("'Year "&$B5&"'"&"!ae5")} -> 557779.95 | H5: {=INDIRECT("'Year "&$B5&"'"&"!ae6")} -> 139444.99 | I5: {=INDIRECT("'Year "&$B5&"'"&"!at5")} -> 663496.62 | J5: {=INDIRECT("'Year "&$B5&"'"&"!at6")} -> 110582.77 | K5: {=INDIRECT("'Year "&$B5&"'"&"!bi5")} -> 874244.23 | L5: {=INDIRECT("'Year "&$B5&"'"&"!bi6")} -> 54640.264 | M5: {=INDIRECT("'Year "&$B5&"'"&"!bx5")} -> 1074891.6 | N5: {=INDIRECT("'Year "&$B5&"'"&"!bx6")} -> 0 | P5: $50M - $200M | Q5: 0.5
B6: 3 | C6: 0.08 | E6: {=INDIRECT("'Year "&$B6&"'"&"!P5")} -> 275246.19 | F6: {=INDIRECT("'Year "&$B6&"'"&"!P6")} -> 206434.64 | G6: {=INDIRECT("'Year "&$B6&"'"&"!ae5")} -> 530521.28 | H6: {=INDIRECT("'Year "&$B6&"'"&"!ae6")} -> 132630.32 | I6: {=INDIRECT("'Year "&$B6&"'"&"!at5")} -> 627279.79 | J6: {=INDIRECT("'Year "&$B6&"'"&"!at6")} -> 104546.63 | K6: {=INDIRECT("'Year "&$B6&"'"&"!bi5")} -> 821267.73 | L6: {=INDIRECT("'Year "&$B6&"'"&"!bi6")} -> 51329.233 | M6: {=INDIRECT("'Year "&$B6&"'"&"!bx5")} -> 998641.88 | N6: {=INDIRECT("'Year "&$B6&"'"&"!bx6")} -> 0 | P6: $200M - $500M | Q6: 0.6
B7: 4 | C7: 0.08 | E7: {=INDIRECT("'Year "&$B7&"'"&"!P5")} -> 265765.62 | F7: {=INDIRECT("'Year "&$B7&"'"&"!P6")} -> 199324.21 | G7: {=INDIRECT("'Year "&$B7&"'"&"!ae5")} -> 504594.74 | H7: {=INDIRECT("'Year "&$B7&"'"&"!ae6")} -> 126148.69 | I7: {=INDIRECT("'Year "&$B7&"'"&"!at5")} -> 593039.86 | J7: {=INDIRECT("'Year "&$B7&"'"&"!at6")} -> 98839.976 | K7: {=INDIRECT("'Year "&$B7&"'"&"!bi5")} -> 771501.45 | L7: {=INDIRECT("'Year "&$B7&"'"&"!bi6")} -> 48218.84 | M7: {=INDIRECT("'Year "&$B7&"'"&"!bx5")} -> 927801.09 | N7: {=INDIRECT("'Year "&$B7&"'"&"!bx6")} -> 0 | P7: $500M – $1B | Q7: 0.8
B8: 5 | C8: 0.08 | E8: {=INDIRECT("'Year "&$B8&"'"&"!P5")} -> 256611.6 | F8: {=INDIRECT("'Year "&$B8&"'"&"!P6")} -> 192458.7 | G8: {=INDIRECT("'Year "&$B8&"'"&"!ae5")} -> 479935.23 | H8: {=INDIRECT("'Year "&$B8&"'"&"!ae6")} -> 119983.81 | I8: {=INDIRECT("'Year "&$B8&"'"&"!at5")} -> 560668.9 | J8: {=INDIRECT("'Year "&$B8&"'"&"!at6")} -> 93444.817 | K8: {=INDIRECT("'Year "&$B8&"'"&"!bi5")} -> 724750.84 | L8: {=INDIRECT("'Year "&$B8&"'"&"!bi6")} -> 45296.928 | M8: {=INDIRECT("'Year "&$B8&"'"&"!bx5")} -> 861985.54 | N8: {=INDIRECT("'Year "&$B8&"'"&"!bx6")} -> 0 | P8: > $1B | Q8: 1
B9: 6 | C9: 0.04 | E9: {=INDIRECT("'Year "&$B9&"'"&"!P5")} -> 124881.54 | F9: {=INDIRECT("'Year "&$B9&"'"&"!P6")} -> 93661.153 | G9: {=INDIRECT("'Year "&$B9&"'"&"!ae5")} -> 230861 | H9: {=INDIRECT("'Year "&$B9&"'"&"!ae6")} -> 57715.251 | I9: {=INDIRECT("'Year "&$B9&"'"&"!at5")} -> 268441.45 | J9: {=INDIRECT("'Year "&$B9&"'"&"!at6")} -> 44740.242 | K9: {=INDIRECT("'Year "&$B9&"'"&"!bi5")} -> 384684.28 | L9: {=INDIRECT("'Year "&$B9&"'"&"!bi6")} -> 24042.767 | M9: {=INDIRECT("'Year "&$B9&"'"&"!bx5")} -> 408081.73 | N9: {=INDIRECT("'Year "&$B9&"'"&"!bx6")} -> 0
B10: 7 | C10: 0.04 | E10: {=INDIRECT("'Year "&$B10&"'"&"!P5")} -> 122713.56 | F10: {=INDIRECT("'Year "&$B10&"'"&"!P6")} -> 92035.166 | G10: {=INDIRECT("'Year "&$B10&"'"&"!ae5")} -> 225155.15 | H10: {=INDIRECT("'Year "&$B10&"'"&"!ae6")} -> 56288.789 | I10: {=INDIRECT("'Year "&$B10&"'"&"!at5")} -> 261020.81 | J10: {=INDIRECT("'Year "&$B10&"'"&"!at6")} -> 43503.468 | K10: {=INDIRECT("'Year "&$B10&"'"&"!bi5")} -> 372863.36 | L10: {=INDIRECT("'Year "&$B10&"'"&"!bi6")} -> 23303.96 | M10: {=INDIRECT("'Year "&$B10&"'"&"!bx5")} -> 393365.64 | N10: {=INDIRECT("'Year "&$B10&"'"&"!bx6")} -> 0
B11: 8 | C11: 0.04 | E11: {=INDIRECT("'Year "&$B11&"'"&"!P5")} -> 120583.21 | F11: {=INDIRECT("'Year "&$B11&"'"&"!P6")} -> 90437.407 | G11: {=INDIRECT("'Year "&$B11&"'"&"!ae5")} -> 219590.33 | H11: {=INDIRECT("'Year "&$B11&"'"&"!ae6")} -> 54897.582 | I11: {=INDIRECT("'Year "&$B11&"'"&"!at5")} -> 253805.29 | J11: {=INDIRECT("'Year "&$B11&"'"&"!at6")} -> 42300.882 | K11: {=INDIRECT("'Year "&$B11&"'"&"!bi5")} -> 361405.69 | L11: {=INDIRECT("'Year "&$B11&"'"&"!bi6")} -> 22587.856 | M11: {=INDIRECT("'Year "&$B11&"'"&"!bx5")} -> 379180.23 | N11: {=INDIRECT("'Year "&$B11&"'"&"!bx6")} -> 0 | P11: Weighting by Project Phase – Hymple DEX
B12: 9 | C12: 0.04 | E12: {=INDIRECT("'Year "&$B12&"'"&"!P5")} -> 118489.85 | F12: {=INDIRECT("'Year "&$B12&"'"&"!P6")} -> 88867.385 | G12: {=INDIRECT("'Year "&$B12&"'"&"!ae5")} -> 214163.04 | H12: {=INDIRECT("'Year "&$B12&"'"&"!ae6")} -> 53540.76 | I12: {=INDIRECT("'Year "&$B12&"'"&"!at5")} -> 246789.24 | J12: {=INDIRECT("'Year "&$B12&"'"&"!at6")} -> 41131.54 | K12: {=INDIRECT("'Year "&$B12&"'"&"!bi5")} -> 350300.1 | L12: {=INDIRECT("'Year "&$B12&"'"&"!bi6")} -> 21893.756 | M12: {=INDIRECT("'Year "&$B12&"'"&"!bx5")} -> 365506.38 | N12: {=INDIRECT("'Year "&$B12&"'"&"!bx6")} -> 0 | P12: Distribution Criteria | Q12: Launch Phase | R12: Growth Phase | S12: Maturity Phase
B13: 10 | C13: 0.04 | E13: {=INDIRECT("'Year "&$B13&"'"&"!P5")} -> 116432.83 | F13: {=INDIRECT("'Year "&$B13&"'"&"!P6")} -> 87324.619 | G13: {=INDIRECT("'Year "&$B13&"'"&"!ae5")} -> 208869.89 | H13: {=INDIRECT("'Year "&$B13&"'"&"!ae6")} -> 52217.472 | I13: {=INDIRECT("'Year "&$B13&"'"&"!at5")} -> 239967.13 | J13: {=INDIRECT("'Year "&$B13&"'"&"!at6")} -> 39994.522 | K13: {=INDIRECT("'Year "&$B13&"'"&"!bi5")} -> 339535.78 | L13: {=INDIRECT("'Year "&$B13&"'"&"!bi6")} -> 21220.986 | M13: {=INDIRECT("'Year "&$B13&"'"&"!bx5")} -> 352325.62 | N13: {=INDIRECT("'Year "&$B13&"'"&"!bx6")} -> 0 | P13: Trading Volume | Q13: 0.45 | R13: 0.35 | S13: 0.3
B14: 11 | C14: 0.02 | E14: {=INDIRECT("'Year "&$B14&"'"&"!P5")} -> 57435.342 | F14: {=INDIRECT("'Year "&$B14&"'"&"!P6")} -> 43076.507 | G14: {=INDIRECT("'Year "&$B14&"'"&"!ae5")} -> 102437.92 | H14: {=INDIRECT("'Year "&$B14&"'"&"!ae6")} -> 25609.48 | I14: {=INDIRECT("'Year "&$B14&"'"&"!at5")} -> 117416.28 | J14: {=INDIRECT("'Year "&$B14&"'"&"!at6")} -> 19569.381 | K14: {=INDIRECT("'Year "&$B14&"'"&"!bi5")} -> 205434.59 | L14: {=INDIRECT("'Year "&$B14&"'"&"!bi6")} -> 12839.662 | M14: {=INDIRECT("'Year "&$B14&"'"&"!bx5")} -> 171473.36 | N14: {=INDIRECT("'Year "&$B14&"'"&"!bx6")} -> 0 | P14: User Activity | Q14: 0.15 | R14: 0.15 | S14: 0.15
B15: 12 | C15: 0.02 | E15: {=INDIRECT("'Year "&$B15&"'"&"!P5")} -> 56934.794 | F15: {=INDIRECT("'Year "&$B15&"'"&"!P6")} -> 42701.095 | G15: {=INDIRECT("'Year "&$B15&"'"&"!ae5")} -> 101164.75 | H15: {=INDIRECT("'Year "&$B15&"'"&"!ae6")} -> 25291.189 | I15: {=INDIRECT("'Year "&$B15&"'"&"!at5")} -> 115782.96 | J15: {=INDIRECT("'Year "&$B15&"'"&"!at6")} -> 19297.16 | K15: {=INDIRECT("'Year "&$B15&"'"&"!bi5")} -> 202255.81 | L15: {=INDIRECT("'Year "&$B15&"'"&"!bi6")} -> 12640.988 | M15: {=INDIRECT("'Year "&$B15&"'"&"!bx5")} -> 168355.75 | N15: {=INDIRECT("'Year "&$B15&"'"&"!bx6")} -> 0 | P15: Liquidity Provision | Q15: 0.25 | R15: 0.3 | S15: 0.2
B16: 13 | C16: 0.02 | E16: {=INDIRECT("'Year "&$B16&"'"&"!P5")} -> 56438.607 | F16: {=INDIRECT("'Year "&$B16&"'"&"!P6")} -> 42328.955 | G16: {=INDIRECT("'Year "&$B16&"'"&"!ae5")} -> 99907.415 | H16: {=INDIRECT("'Year "&$B16&"'"&"!ae6")} -> 24976.854 | I16: {=INDIRECT("'Year "&$B16&"'"&"!at5")} -> 114172.36 | J16: {=INDIRECT("'Year "&$B16&"'"&"!at6")} -> 19028.727 | K16: {=INDIRECT("'Year "&$B16&"'"&"!bi5")} -> 199126.22 | L16: {=INDIRECT("'Year "&$B16&"'"&"!bi6")} -> 12445.389 | M16: {=INDIRECT("'Year "&$B16&"'"&"!bx5")} -> 165294.82 | N16: {=INDIRECT("'Year "&$B16&"'"&"!bx6")} -> 0 | P16: Token Staking | Q16: 0.05 | R16: 0.05 | S16: 0.2
B17: 14 | C17: 0.02 | E17: {=INDIRECT("'Year "&$B17&"'"&"!P5")} -> 55946.745 | F17: {=INDIRECT("'Year "&$B17&"'"&"!P6")} -> 41960.059 | G17: {=INDIRECT("'Year "&$B17&"'"&"!ae5")} -> 98665.703 | H17: {=INDIRECT("'Year "&$B17&"'"&"!ae6")} -> 24666.426 | I17: {=INDIRECT("'Year "&$B17&"'"&"!at5")} -> 112584.17 | J17: {=INDIRECT("'Year "&$B17&"'"&"!at6")} -> 18764.028 | K17: {=INDIRECT("'Year "&$B17&"'"&"!bi5")} -> 196045.06 | L17: {=INDIRECT("'Year "&$B17&"'"&"!bi6")} -> 12252.816 | M17: {=INDIRECT("'Year "&$B17&"'"&"!bx5")} -> 162289.54 | N17: {=INDIRECT("'Year "&$B17&"'"&"!bx6")} -> 0 | P17: Qualified Interactions | Q17: 0.05 | R17: 0.05 | S17: 0.1
B18: 15 | C18: 0.02 | E18: {=INDIRECT("'Year "&$B18&"'"&"!P5")} -> 55946.745 | F18: {=INDIRECT("'Year "&$B18&"'"&"!P6")} -> 41960.059 | G18: {=INDIRECT("'Year "&$B18&"'"&"!ae5")} -> 98665.703 | H18: {=INDIRECT("'Year "&$B18&"'"&"!ae6")} -> 24666.426 | I18: {=INDIRECT("'Year "&$B18&"'"&"!at5")} -> 112584.17 | J18: {=INDIRECT("'Year "&$B18&"'"&"!at6")} -> 18764.028 | K18: {=INDIRECT("'Year "&$B18&"'"&"!bi5")} -> 196045.06 | L18: {=INDIRECT("'Year "&$B18&"'"&"!bi6")} -> 12252.816 | M18: {=INDIRECT("'Year "&$B18&"'"&"!bx5")} -> 162289.54 | N18: {=INDIRECT("'Year "&$B18&"'"&"!bx6")} -> 0 | P18: Proof of Referral (PoR) | Q18: 0.1 | R18: 0.15 | S18: 0.05
B19: 16 | C19: 0.02 | E19: {=INDIRECT("'Year "&$B19&"'"&"!P5")} -> 0 | F19: {=INDIRECT("'Year "&$B19&"'"&"!P6")} -> 0 | G19: {=INDIRECT("'Year "&$B19&"'"&"!ae5")} -> 0 | H19: {=INDIRECT("'Year "&$B19&"'"&"!ae6")} -> 0 | I19: {=INDIRECT("'Year "&$B19&"'"&"!at5")} -> 0 | J19: {=INDIRECT("'Year "&$B19&"'"&"!at6")} -> 0 | K19: {=INDIRECT("'Year "&$B19&"'"&"!bi5")} -> 0 | L19: {=INDIRECT("'Year "&$B19&"'"&"!bi6")} -> 0 | M19: {=INDIRECT("'Year "&$B19&"'"&"!bx5")} -> 0 | N19: {=INDIRECT("'Year "&$B19&"'"&"!bx6")} -> 0 | P19: Loyalty & Retention (Bonus) | Q19: 0.05 | R19: 0.05 | S19: 0.1
B20: 17 | C20: 0.02 | E20: {=INDIRECT("'Year "&$B20&"'"&"!P5")} -> 0 | F20: {=INDIRECT("'Year "&$B20&"'"&"!P6")} -> 0 | G20: {=INDIRECT("'Year "&$B20&"'"&"!ae5")} -> 0 | H20: {=INDIRECT("'Year "&$B20&"'"&"!ae6")} -> 0 | I20: {=INDIRECT("'Year "&$B20&"'"&"!at5")} -> 0 | J20: {=INDIRECT("'Year "&$B20&"'"&"!at6")} -> 0 | K20: {=INDIRECT("'Year "&$B20&"'"&"!bi5")} -> 0 | L20: {=INDIRECT("'Year "&$B20&"'"&"!bi6")} -> 0 | M20: {=INDIRECT("'Year "&$B20&"'"&"!bx5")} -> 0 | N20: {=INDIRECT("'Year "&$B20&"'"&"!bx6")} -> 0 | P20: Total | Q20: =SUM(Q13:Q19) -> 1.1 | R20: =SUM(R13:R19) -> 1.1 | S20: =SUM(S13:S19) -> 1.1
B21: 18 | C21: 0.02 | E21: {=INDIRECT("'Year "&$B21&"'"&"!P5")} -> 0 | F21: {=INDIRECT("'Year "&$B21&"'"&"!P6")} -> 0 | G21: {=INDIRECT("'Year "&$B21&"'"&"!ae5")} -> 0 | H21: {=INDIRECT("'Year "&$B21&"'"&"!ae6")} -> 0 | I21: {=INDIRECT("'Year "&$B21&"'"&"!at5")} -> 0 | J21: {=INDIRECT("'Year "&$B21&"'"&"!at6")} -> 0 | K21: {=INDIRECT("'Year "&$B21&"'"&"!bi5")} -> 0 | L21: {=INDIRECT("'Year "&$B21&"'"&"!bi6")} -> 0 | M21: {=INDIRECT("'Year "&$B21&"'"&"!bx5")} -> 0 | N21: {=INDIRECT("'Year "&$B21&"'"&"!bx6")} -> 0
B22: 19 | C22: 0.02 | E22: {=INDIRECT("'Year "&$B22&"'"&"!P5")} -> 0 | F22: {=INDIRECT("'Year "&$B22&"'"&"!P6")} -> 0 | G22: {=INDIRECT("'Year "&$B22&"'"&"!ae5")} -> 0 | H22: {=INDIRECT("'Year "&$B22&"'"&"!ae6")} -> 0 | I22: {=INDIRECT("'Year "&$B22&"'"&"!at5")} -> 0 | J22: {=INDIRECT("'Year "&$B22&"'"&"!at6")} -> 0 | K22: {=INDIRECT("'Year "&$B22&"'"&"!bi5")} -> 0 | L22: {=INDIRECT("'Year "&$B22&"'"&"!bi6")} -> 0 | M22: {=INDIRECT("'Year "&$B22&"'"&"!bx5")} -> 0 | N22: {=INDIRECT("'Year "&$B22&"'"&"!bx6")} -> 0
B23: 20 | C23: 0.02 | E23: {=INDIRECT("'Year "&$B23&"'"&"!P5")} -> 0 | F23: {=INDIRECT("'Year "&$B23&"'"&"!P6")} -> 0 | G23: {=INDIRECT("'Year "&$B23&"'"&"!ae5")} -> 0 | H23: {=INDIRECT("'Year "&$B23&"'"&"!ae6")} -> 0 | I23: {=INDIRECT("'Year "&$B23&"'"&"!at5")} -> 0 | J23: {=INDIRECT("'Year "&$B23&"'"&"!at6")} -> 0 | K23: {=INDIRECT("'Year "&$B23&"'"&"!bi5")} -> 0 | L23: {=INDIRECT("'Year "&$B23&"'"&"!bi6")} -> 0 | M23: {=INDIRECT("'Year "&$B23&"'"&"!bx5")} -> 0 | N23: {=INDIRECT("'Year "&$B23&"'"&"!bx6")} -> 0
B24: 21 | C24: 0.02 | E24: {=INDIRECT("'Year "&$B24&"'"&"!P5")} -> 0 | F24: {=INDIRECT("'Year "&$B24&"'"&"!P6")} -> 0 | G24: {=INDIRECT("'Year "&$B24&"'"&"!ae5")} -> 0 | H24: {=INDIRECT("'Year "&$B24&"'"&"!ae6")} -> 0 | I24: {=INDIRECT("'Year "&$B24&"'"&"!at5")} -> 0 | J24: {=INDIRECT("'Year "&$B24&"'"&"!at6")} -> 0 | K24: {=INDIRECT("'Year "&$B24&"'"&"!bi5")} -> 0 | L24: {=INDIRECT("'Year "&$B24&"'"&"!bi6")} -> 0 | M24: {=INDIRECT("'Year "&$B24&"'"&"!bx5")} -> 0 | N24: {=INDIRECT("'Year "&$B24&"'"&"!bx6")} -> 0
B25: 22 | C25: 0.02 | E25: {=INDIRECT("'Year "&$B25&"'"&"!P5")} -> 0 | F25: {=INDIRECT("'Year "&$B25&"'"&"!P6")} -> 0 | G25: {=INDIRECT("'Year "&$B25&"'"&"!ae5")} -> 0 | H25: {=INDIRECT("'Year "&$B25&"'"&"!ae6")} -> 0 | I25: {=INDIRECT("'Year "&$B25&"'"&"!at5")} -> 0 | J25: {=INDIRECT("'Year "&$B25&"'"&"!at6")} -> 0 | K25: {=INDIRECT("'Year "&$B25&"'"&"!bi5")} -> 0 | L25: {=INDIRECT("'Year "&$B25&"'"&"!bi6")} -> 0 | M25: {=INDIRECT("'Year "&$B25&"'"&"!bx5")} -> 0 | N25: {=INDIRECT("'Year "&$B25&"'"&"!bx6")} -> 0
B26: 23 | C26: 0.02 | E26: {=INDIRECT("'Year "&$B26&"'"&"!P5")} -> 0 | F26: {=INDIRECT("'Year "&$B26&"'"&"!P6")} -> 0 | G26: {=INDIRECT("'Year "&$B26&"'"&"!ae5")} -> 0 | H26: {=INDIRECT("'Year "&$B26&"'"&"!ae6")} -> 0 | I26: {=INDIRECT("'Year "&$B26&"'"&"!at5")} -> 0 | J26: {=INDIRECT("'Year "&$B26&"'"&"!at6")} -> 0 | K26: {=INDIRECT("'Year "&$B26&"'"&"!bi5")} -> 0 | L26: {=INDIRECT("'Year "&$B26&"'"&"!bi6")} -> 0 | M26: {=INDIRECT("'Year "&$B26&"'"&"!bx5")} -> 0 | N26: {=INDIRECT("'Year "&$B26&"'"&"!bx6")} -> 0
B27: 24 | C27: 0.02 | E27: {=INDIRECT("'Year "&$B27&"'"&"!P5")} -> 0 | F27: {=INDIRECT("'Year "&$B27&"'"&"!P6")} -> 0 | G27: {=INDIRECT("'Year "&$B27&"'"&"!ae5")} -> 0 | H27: {=INDIRECT("'Year "&$B27&"'"&"!ae6")} -> 0 | I27: {=INDIRECT("'Year "&$B27&"'"&"!at5")} -> 0 | J27: {=INDIRECT("'Year "&$B27&"'"&"!at6")} -> 0 | K27: {=INDIRECT("'Year "&$B27&"'"&"!bi5")} -> 0 | L27: {=INDIRECT("'Year "&$B27&"'"&"!bi6")} -> 0 | M27: {=INDIRECT("'Year "&$B27&"'"&"!bx5")} -> 0 | N27: {=INDIRECT("'Year "&$B27&"'"&"!bx6")} -> 0
B28: 25 | C28: 0.02 | E28: {=INDIRECT("'Year "&$B28&"'"&"!P5")} -> 0 | F28: {=INDIRECT("'Year "&$B28&"'"&"!P6")} -> 0 | G28: {=INDIRECT("'Year "&$B28&"'"&"!ae5")} -> 0 | H28: {=INDIRECT("'Year "&$B28&"'"&"!ae6")} -> 0 | I28: {=INDIRECT("'Year "&$B28&"'"&"!at5")} -> 0 | J28: {=INDIRECT("'Year "&$B28&"'"&"!at6")} -> 0 | K28: {=INDIRECT("'Year "&$B28&"'"&"!bi5")} -> 0 | L28: {=INDIRECT("'Year "&$B28&"'"&"!bi6")} -> 0 | M28: {=INDIRECT("'Year "&$B28&"'"&"!bx5")} -> 0 | N28: {=INDIRECT("'Year "&$B28&"'"&"!bx6")} -> 0
B29: 26 | C29: 0.02 | E29: {=INDIRECT("'Year "&$B29&"'"&"!P5")} -> 0 | F29: {=INDIRECT("'Year "&$B29&"'"&"!P6")} -> 0 | G29: {=INDIRECT("'Year "&$B29&"'"&"!ae5")} -> 0 | H29: {=INDIRECT("'Year "&$B29&"'"&"!ae6")} -> 0 | I29: {=INDIRECT("'Year "&$B29&"'"&"!at5")} -> 0 | J29: {=INDIRECT("'Year "&$B29&"'"&"!at6")} -> 0 | K29: {=INDIRECT("'Year "&$B29&"'"&"!bi5")} -> 0 | L29: {=INDIRECT("'Year "&$B29&"'"&"!bi6")} -> 0 | M29: {=INDIRECT("'Year "&$B29&"'"&"!bx5")} -> 0 | N29: {=INDIRECT("'Year "&$B29&"'"&"!bx6")} -> 0
B30: 27 | C30: 0.02 | E30: {=INDIRECT("'Year "&$B30&"'"&"!P5")} -> 0 | F30: {=INDIRECT("'Year "&$B30&"'"&"!P6")} -> 0 | G30: {=INDIRECT("'Year "&$B30&"'"&"!ae5")} -> 0 | H30: {=INDIRECT("'Year "&$B30&"'"&"!ae6")} -> 0 | I30: {=INDIRECT("'Year "&$B30&"'"&"!at5")} -> 0 | J30: {=INDIRECT("'Year "&$B30&"'"&"!at6")} -> 0 | K30: {=INDIRECT("'Year "&$B30&"'"&"!bi5")} -> 0 | L30: {=INDIRECT("'Year "&$B30&"'"&"!bi6")} -> 0 | M30: {=INDIRECT("'Year "&$B30&"'"&"!bx5")} -> 0 | N30: {=INDIRECT("'Year "&$B30&"'"&"!bx6")} -> 0
B31: 28 | C31: 0.02 | E31: {=INDIRECT("'Year "&$B31&"'"&"!P5")} -> 0 | F31: {=INDIRECT("'Year "&$B31&"'"&"!P6")} -> 0 | G31: {=INDIRECT("'Year "&$B31&"'"&"!ae5")} -> 0 | H31: {=INDIRECT("'Year "&$B31&"'"&"!ae6")} -> 0 | I31: {=INDIRECT("'Year "&$B31&"'"&"!at5")} -> 0 | J31: {=INDIRECT("'Year "&$B31&"'"&"!at6")} -> 0 | K31: {=INDIRECT("'Year "&$B31&"'"&"!bi5")} -> 0 | L31: {=INDIRECT("'Year "&$B31&"'"&"!bi6")} -> 0 | M31: {=INDIRECT("'Year "&$B31&"'"&"!bx5")} -> 0 | N31: {=INDIRECT("'Year "&$B31&"'"&"!bx6")} -> 0
B32: 29 | C32: 0.02 | E32: {=INDIRECT("'Year "&$B32&"'"&"!P5")} -> 0 | F32: {=INDIRECT("'Year "&$B32&"'"&"!P6")} -> 0 | G32: {=INDIRECT("'Year "&$B32&"'"&"!ae5")} -> 0 | H32: {=INDIRECT("'Year "&$B32&"'"&"!ae6")} -> 0 | I32: {=INDIRECT("'Year "&$B32&"'"&"!at5")} -> 0 | J32: {=INDIRECT("'Year "&$B32&"'"&"!at6")} -> 0 | K32: {=INDIRECT("'Year "&$B32&"'"&"!bi5")} -> 0 | L32: {=INDIRECT("'Year "&$B32&"'"&"!bi6")} -> 0 | M32: {=INDIRECT("'Year "&$B32&"'"&"!bx5")} -> 0 | N32: {=INDIRECT("'Year "&$B32&"'"&"!bx6")} -> 0
... B53: 50 | C53: 0.02 | E53: {=INDIRECT("'Year "&$B53&"'"&"!P5")} -> 0 | F53: {=INDIRECT("'Year "&$B53&"'"&"!P6")} -> 0 | G53: {=INDIRECT("'Year "&$B53&"'"&"!ae5")} -> 0 | H53: {=INDIRECT("'Year "&$B53&"'"&"!ae6")} -> 0 | I53: {=INDIRECT("'Year "&$B53&"'"&"!at5")} -> 0 | J53: {=INDIRECT("'Year "&$B53&"'"&"!at6")} -> 0 | K53: {=INDIRECT("'Year "&$B53&"'"&"!bi5")} -> 0 | L53: {=INDIRECT("'Year "&$B53&"'"&"!bi6")} -> 0 | M53: {=INDIRECT("'Year "&$B53&"'"&"!bx5")} -> 0 | N53: {=INDIRECT("'Year "&$B53&"'"&"!bx6")} -> 0

Sheet Year 1
D1: 15000000 | E1: =D1-(D5+D6) -> 14956250 | F1: =E1-(E5+E6) -> 14912628 | G1: =F1-(F5+F6) -> 14869132 | H1: =G1-(G5+G6) -> 14825764 | I1: =H1-(H5+H6) -> 14782522 | J1: =I1-(I5+I6) -> 14739407 | K1: =J1-(J5+J6) -> 14696417 | L1: =K1-(K5+K6) -> 14653552 | ... P1: =O1-(O5+O6) -> 14483341 | S1: 15000000 | T1: =S1-(S5+S6) -> 14937500 | U1: =T1-(T5+T6) -> 14875260 | V1: =U1-(U5+U6) -> 14813280 | W1: =V1-(V5+V6) -> 14751558 | X1: =W1-(W5+W6) -> 14690093 | Y1: =X1-(X5+X6) -> 14628885 | Z1: =Y1-(Y5+Y6) -> 14567931 | AA1: =Z1-(Z5+Z6) -> 14507231 | ... AE1: =AD1-(AD5+AD6) -> 14266951 | AH1: 15000000 | AI1: =AH1-(AH5+AH6) -> 14930000 | AJ1: =AI1-(AI5+AI6) -> 14860327 | AK1: =AJ1-(AJ5+AJ6) -> 14790978 | AL1: =AK1-(AK5+AK6) -> 14721954 | AM1: =AL1-(AL5+AL6) -> 14653251 | AN1: =AM1-(AM5+AM6) -> 14584870 | AO1: =AN1-(AN5+AN6) -> 14516807 | AP1: =AO1-(AO5+AO6) -> 14449062 | ... AT1: =AS1-(AS5+AS6) -> 14181228 | AW1: 15000000 | AX1: =AW1-(AW5+AW6) -> 14915000 | AY1: =AX1-(AX5+AX6) -> 14830482 | AZ1: =AY1-(AY5+AY6) -> 14746442 | BA1: =AZ1-(AZ5+AZ6) -> 14662879 | BB1: =BA1-(BA5+BA6) -> 14579789 | BC1: =BB1-(BB5+BB6) -> 14497171 | BD1: =BC1-(BC5+BC6) -> 14415020 | BE1: =BD1-(BD5+BD6) -> 14333335 | ... BI1: =BH1-(BH5+BH6) -> 14011197 | BL1: 15000000 | BM1: =BL1-(BL5+BL6) -> 14900000 | BN1: =BM1-(BM5+BM6) -> 14800667 | BO1: =BN1-(BN5+BN6) -> 14701996 | BP1: =BO1-(BO5+BO6) -> 14603982 | BQ1: =BP1-(BP5+BP6) -> 14506622 | BR1: =BQ1-(BQ5+BQ6) -> 14409912 | BS1: =BR1-(BR5+BR6) -> 14313845 | BT1: =BS1-(BS5+BS6) -> 14218420 | ... BX1: =BW1-(BW5+BW6) -> 13843037
A2: 1 | B2: Burn | C2: Volume <= $50M | R2: Volume $50M - $200M | AG2: Volume $200M - $500M | AV2: Volume $500M – $1B | BK2: Volume > $1B
B3: =Simulations!$B$1 -> 0.25 | C3: 0.25 | D3: Jan | E3: Feb | F3: Mar | G3: Apr | H3: May | I3: Jun | J3: Jul | K3: Aug | L3: Sep | M3: Oct | N3: Nov | O3: Dec | P3: Remaining | R3: 0.5 | S3: Jan | T3: Feb | U3: Mar | V3: Apr | W3: May | X3: Jun | Y3: Jul | Z3: Aug | AA3: Sep | AB3: Oct | AC3: Nov | AD3: Dec | AE3: Remaining | AG3: 0.6 | AH3: Jan | AI3: Feb | AJ3: Mar | AK3: Apr | AL3: May | AM3: Jun | AN3: Jul | AO3: Aug | AP3: Sep | AQ3: Oct | AR3: Nov | AS3: Dec | AT3: Remaining | AV3: 0.8 | AW3: Jan | AX3: Feb | AY3: Mar | AZ3: Apr | BA3: May | BB3: Jun | BC3: Jul | BD3: Aug | BE3: Sep | BF3: Oct | BG3: Nov | BH3: Dec | BI3: Remaining | BK3: 1 | BL3: Jan | BM3: Feb | BN3: Mar | BO3: Apr | BP3: May | BQ3: Jun | BR3: Jul | BS3: Aug | BT3: Sep | BU3: Oct | BV3: Nov | BW3: Dec | BX3: Remaining
C4: Monthly maximum | D4: {=INDIRECT("Simulations!$c$"&$A$2+3)*(D1/12)} -> 100000 | E4: {=INDIRECT("Simulations!$c$"&$A$2+3)*(E1/12)} -> 99708.333 | F4: {=INDIRECT("Simulations!$c$"&$A$2+3)*(F1/12)} -> 99417.517 | G4: {=INDIRECT("Simulations!$c$"&$A$2+3)*(G1/12)} -> 99127.55 | H4: {=INDIRECT("Simulations!$c$"&$A$2+3)*(H1/12)} -> 98838.428 | I4: {=INDIRECT("Simulations!$c$"&$A$2+3)*(I1/12)} -> 98550.149 | J4: {=INDIRECT("Simulations!$c$"&$A$2+3)*(J1/12)} -> 98262.711 | K4: {=INDIRECT("Simulations!$c$"&$A$2+3)*(K1/12)} -> 97976.111 | ... O4: {=INDIRECT("Simulations!$c$"&$A$2+3)*(O1/12)} -> 96838.048 | P4: =Simulations!$D$1-($P$5+$P$6) -> 14483341 | R4: Monthly maximum | S4: {=INDIRECT("Simulations!$c$"&$A$2+3)*(S1/12)} -> 100000 | T4: {=(INDIRECT("Simulations!$c$"&$A$2+3)*(T1/12))} -> 99583.333 | U4: {=(INDIRECT("Simulations!$c$"&$A$2+3)*(U1/12))} -> 99168.403 | V4: {=(INDIRECT("Simulations!$c$"&$A$2+3)*(V1/12))} -> 98755.201 | W4: {=(INDIRECT("Simulations!$c$"&$A$2+3)*(W1/12))} -> 98343.721 | X4: {=(INDIRECT("Simulations!$c$"&$A$2+3)*(X1/12))} -> 97933.956 | Y4: {=(INDIRECT("Simulations!$c$"&$A$2+3)*(Y1/12))} -> 97525.897 | Z4: {=(INDIRECT("Simulations!$c$"&$A$2+3)*(Z1/12))} -> 97119.54 | AA4: {=(INDIRECT("Simulations!$c$"&$A$2+3)*(AA1/12))} -> 96714.875 | ... AD4: {=(INDIRECT("Simulations!$c$"&$A$2+3)*(AD1/12))} -> 95510.969 | AE4: =Simulations!$D$1-($AE$5+$AE$6) -> 14266951 | AG4: Monthly maximum | AH4: {=INDIRECT("Simulations!$c$"&$A$2+3)*(AH1/12)} -> 100000 | AI4: {=INDIRECT("Simulations!$c$"&$A$2+3)*(AI1/12)} -> 99533.333 | AJ4: {=INDIRECT("Simulations!$c$"&$A$2+3)*(AJ1/12)} -> 99068.844 | AK4: {=INDIRECT("Simulations!$c$"&$A$2+3)*(AK1/12)} -> 98606.523 | AL4: {=INDIRECT("Simulations!$c$"&$A$2+3)*(AL1/12)} -> 98146.359 | AM4: {=INDIRECT("Simulations!$c$"&$A$2+3)*(AM1/12)} -> 97688.343 | AN4: {=INDIRECT("Simulations!$c$"&$A$2+3)*(AN1/12)} -> 97232.464 | AO4: {=INDIRECT("Simulations!$c$"&$A$2+3)*(AO1/12)} -> 96778.713 | ... AS4: {=INDIRECT("Simulations!$c$"&$A$2+3)*(AS1/12)} -> 94984.783 | AT4: =Simulations!$D$1-($AT$5+$AT$6) -> 14181228 | AV4: Monthly maximum | AW4: 100000 | AX4: {=(INDIRECT("Simulations!$c$"&$A$2+3)*(AX1/12))} -> 99433.333 | AY4: {=(INDIRECT("Simulations!$c$"&$A$2+3)*(AY1/12))} -> 98869.878 | AZ4: {=(INDIRECT("Simulations!$c$"&$A$2+3)*(AZ1/12))} -> 98309.615 | BA4: {=(INDIRECT("Simulations!$c$"&$A$2+3)*(BA1/12))} -> 97752.527 | BB4: {=(INDIRECT("Simulations!$c$"&$A$2+3)*(BB1/12))} -> 97198.596 | BC4: {=(INDIRECT("Simulations!$c$"&$A$2+3)*(BC1/12))} -> 96647.804 | BD4: {=(INDIRECT("Simulations!$c$"&$A$2+3)*(BD1/12))} -> 96100.133 | BE4: {=(INDIRECT("Simulations!$c$"&$A$2+3)*(BE1/12))} -> 95555.566 | ... BH4: {=(INDIRECT("Simulations!$c$"&$A$2+3)*(BH1/12))} -> 93940.309 | BI4: =Simulations!$D$1-($BI$5+$BI$6) -> 14011197 | BK4: Monthly maximum | BL4: {=INDIRECT("Simulations!$c$"&$A$2+3)*Simulations!$D$1/12} -> 100000 | BM4: {=INDIRECT("Simulations!$c$"&$A$2+3)*(BM1/12)} -> 99333.333 | BN4: {=INDIRECT("Simulations!$c$"&$A$2+3)*(BN1/12)} -> 98671.111 | BO4: {=INDIRECT("Simulations!$c$"&$A$2+3)*(BO1/12)} -> 98013.304 | BP4: {=INDIRECT("Simulations!$c$"&$A$2+3)*(BP1/12)} -> 97359.882 | BQ4: {=INDIRECT("Simulations!$c$"&$A$2+3)*(BQ1/12)} -> 96710.816 | BR4: {=INDIRECT("Simulations!$c$"&$A$2+3)*(BR1/12)} -> 96066.077 | BS4: {=INDIRECT("Simulations!$c$"&$A$2+3)*(BS1/12)} -> 95425.637 | BT4: {=INDIRECT("Simulations!$c$"&$A$2+3)*(BT1/12)} -> 94789.466 | ... BW4: {=INDIRECT("Simulations!$c$"&$A$2+3)*(BW1/12)} -> 92906.287 | BX4: =Simulations!$D$1-($BX$5+$BX$6) -> 13843037
C5: Total Distributed | D5: =$C$3*D4 -> 25000 | E5: =$C$3*E4 -> 24927.083 | F5: =$C$3*F4 -> 24854.379 | G5: =$C$3*G4 -> 24781.887 | H5: =$C$3*H4 -> 24709.607 | I5: =$C$3*I4 -> 24637.537 | J5: =$C$3*J4 -> 24565.678 | K5: =$C$3*K4 -> 24494.028 | ... O5: =$C$3*O4 -> 24209.512 | P5: =SUM(D5:O5) -> 295233.98 | R5: Total Distributed | S5: =$R$3*S4 -> 50000 | T5: =$R$3*T4 -> 49791.667 | U5: =$R$3*U4 -> 49584.201 | V5: =$R$3*V4 -> 49377.601 | W5: =$R$3*W4 -> 49171.861 | X5: =$R$3*X4 -> 48966.978 | Y5: =$R$3*Y4 -> 48762.949 | Z5: =$R$3*Z4 -> 48559.77 | ... AD5: =$R$3*AD4 -> 47755.485 | AE5: =SUM(S5:AD5) -> 586439.19 | AG5: Total Distributed | AH5: =$AG$3*AH4 -> 60000 | AI5: =$AG$3*AI4 -> 59720 | AJ5: =$AG$3*AJ4 -> 59441.307 | AK5: =$AG$3*AK4 -> 59163.914 | AL5: =$AG$3*AL4 -> 58887.816 | AM5: =$AG$3*AM4 -> 58613.006 | AN5: =$AG$3*AN4 -> 58339.478 | AO5: =$AG$3*AO4 -> 58067.228 | ... AS5: =$AG$3*AS4 -> 56990.87 | AT5: =SUM(AH5:AS5) -> 701804.47 | AV5: Total Distributed | AW5: =$AV$3*AW4 -> 80000 | AX5: =$AV$3*AX4 -> 79546.667 | AY5: =$AV$3*AY4 -> 79095.902 | AZ5: =$AV$3*AZ4 -> 78647.692 | BA5: =$AV$3*BA4 -> 78202.022 | BB5: =$AV$3*BB4 -> 77758.877 | BC5: =$AV$3*BC4 -> 77318.243 | BD5: =$AV$3*BD4 -> 76880.107 | ... BH5: =$AV$3*BH4 -> 75152.247 | BI5: =SUM(AW5:BH5) -> 930638.01 | BK5: Total Distributed | BL5: =$BK$3*BL4 -> 100000 | BM5: =$BK$3*BM4 -> 99333.333 | BN5: =$BK$3*BN4 -> 98671.111 | BO5: =$BK$3*BO4 -> 98013.304 | BP5: =$BK$3*BP4 -> 97359.882 | BQ5: =$BK$3*BQ4 -> 96710.816 | BR5: =$BK$3*BR4 -> 96066.077 | BS5: =$BK$3*BS4 -> 95425.637 | ... BW5: =$BK$3*BW4 -> 92906.287 | BX5: =SUM(BL5:BW5) -> 1156963.3
C6: Total Burned | D6: =$B$3*(D4-D5) -> 18750 | E6: =$B$3*(E4-E5) -> 18695.312 | F6: =$B$3*(F4-F5) -> 18640.785 | G6: =$B$3*(G4-G5) -> 18586.416 | H6: =$B$3*(H4-H5) -> 18532.205 | I6: =$B$3*(I4-I5) -> 18478.153 | J6: =$B$3*(J4-J5) -> 18424.258 | K6: =$B$3*(K4-K5) -> 18370.521 | ... O6: =$B$3*(O4-O5) -> 18157.134 | P6: =SUM(D6:O6) -> 221425.49 | R6: Total Burned | S6: =$B$3*(S4-S5) -> 12500 | T6: =$B$3*(T4-T5) -> 12447.917 | U6: =$B$3*(U4-U5) -> 12396.05 | V6: =$B$3*(V4-V5) -> 12344.4 | W6: =$B$3*(W4-W5) -> 12292.965 | X6: =$B$3*(X4-X5) -> 12241.744 | Y6: =$B$3*(Y4-Y5) -> 12190.737 | Z6: =$B$3*(Z4-Z5) -> 12139.942 | ... AD6: =$B$3*(AD4-AD5) -> 11938.871 | AE6: =SUM(S6:AD6) -> 146609.8 | AG6: Total Burned | AH6: =$B$3*(AH4-AH5) -> 10000 | AI6: =$B$3*(AI4-AI5) -> 9953.3333 | AJ6: =$B$3*(AJ4-AJ5) -> 9906.8844 | AK6: =$B$3*(AK4-AK5) -> 9860.6523 | AL6: =$B$3*(AL4-AL5) -> 9814.6359 | AM6: =$B$3*(AM4-AM5) -> 9768.8343 | AN6: =$B$3*(AN4-AN5) -> 9723.2464 | AO6: =$B$3*(AO4-AO5) -> 9677.8713 | ... AS6: =$B$3*(AS4-AS5) -> 9498.4783 | AT6: =SUM(AH6:AS6) -> 116967.41 | AV6: Total Burned | AW6: =$B$3*(AW4-AW5) -> 5000 | AX6: =$B$3*(AX4-AX5) -> 4971.6667 | AY6: =$B$3*(AY4-AY5) -> 4943.4939 | AZ6: =$B$3*(AZ4-AZ5) -> 4915.4808 | BA6: =$B$3*(BA4-BA5) -> 4887.6264 | BB6: =$B$3*(BB4-BB5) -> 4859.9298 | BC6: =$B$3*(BC4-BC5) -> 4832.3902 | BD6: =$B$3*(BD4-BD5) -> 4805.0067 | ... BH6: =$B$3*(BH4-BH5) -> 4697.0155 | BI6: =SUM(AW6:BH6) -> 58164.876 | BK6: Total Burned | BL6: =$B$3*(BL4-BL5) -> 0 | BM6: =$B$3*(BM4-BM5) -> 0 | BN6: =$B$3*(BN4-BN5) -> 0 | BO6: =$B$3*(BO4-BO5) -> 0 | BP6: =$B$3*(BP4-BP5) -> 0 | BQ6: =$B$3*(BQ4-BQ5) -> 0 | BR6: =$B$3*(BR4-BR5) -> 0 | BS6: =$B$3*(BS4-BS5) -> 0 | ... BW6: =$B$3*(BW4-BW5) -> 0 | BX6: =SUM(BL6:BW6) -> 0
A7: User | B7: User Score | C7: Pool Participation | D7: User Receives | E7: User Receives | F7: User Receives | G7: User Receives | H7: User Receives | I7: User Receives | J7: User Receives | K7: User Receives | L7: User Receives | M7: User Receives | N7: User Receives | O7: User Receives | S7: User Receives | T7: User Receives | U7: User Receives | V7: User Receives | W7: User Receives | X7: User Receives | Y7: User Receives | Z7: User Receives | AA7: User Receives | AB7: User Receives | AC7: User Receives | AD7: User Receives | AH7: User Receives | AI7: User Receives | AJ7: User Receives | AK7: User Receives | AL7: User Receives | AM7: User Receives | AN7: User Receives | AO7: User Receives | AP7: User Receives | AQ7: User Receives | AR7: User Receives | AS7: User Receives | AW7: User Receives | AX7: User Receives | AY7: User Receives | AZ7: User Receives | BA7: User Receives | BB7: User Receives | BC7: User Receives | BD7: User Receives | BE7: User Receives | BF7: User Receives | BG7: User Receives | BH7: User Receives | BL7: User Receives | BM7: User Receives | BN7: User Receives | BO7: User Receives | BP7: User Receives | BQ7: User Receives | BR7: User Receives | BS7: User Receives | BT7: User Receives | BU7: User Receives | BV7: User Receives | BW7: User Receives
A8: 1 | B8: 1.1 | C8: =B8/SUM($B$8:$B$107) -> 0.019321974 | D8: =IF($C8*D$5>(5%*D$5),(5%*D$5)*$B8,$C8*D$5) -> 483.04936 | E8: =IF($C8*E$5>(5%*E$5),(5%*E$5)*$B8,$C8*E$5) -> 481.64046 | F8: =IF($C8*F$5>(5%*F$5),(5%*F$5)*$B8,$C8*F$5) -> 480.23568 | G8: =IF($C8*G$5>(5%*G$5),(5%*G$5)*$B8,$C8*G$5) -> 478.83499 | H8: =IF($C8*H$5>(5%*H$5),(5%*H$5)*$B8,$C8*H$5) -> 477.43839 | I8: =IF($C8*I$5>(5%*I$5),(5%*I$5)*$B8,$C8*I$5) -> 476.04586 | J8: =IF($C8*J$5>(5%*J$5),(5%*J$5)*$B8,$C8*J$5) -> 474.6574 | K8: =IF($C8*K$5>(5%*K$5),(5%*K$5)*$B8,$C8*K$5) -> 473.27298 | ... O8: =IF($C8*O$5>(5%*O$5),(5%*O$5)*$B8,$C8*O$5) -> 467.77557 | S8: =IF($C8*S$5>(5%*S$5),(5%*S$5)*$B8,$C8*S$5) -> 966.09872 | T8: =IF($C8*T$5>(5%*T$5),(5%*T$5)*$B8,$C8*T$5) -> 962.07331 | U8: =IF($C8*U$5>(5%*U$5),(5%*U$5)*$B8,$C8*U$5) -> 958.06467 | V8: =IF($C8*V$5>(5%*V$5),(5%*V$5)*$B8,$C8*V$5) -> 954.07273 | W8: =IF($C8*W$5>(5%*W$5),(5%*W$5)*$B8,$C8*W$5) -> 950.09743 | X8: =IF($C8*X$5>(5%*X$5),(5%*X$5)*$B8,$C8*X$5) -> 946.13869 | Y8: =IF($C8*Y$5>(5%*Y$5),(5%*Y$5)*$B8,$C8*Y$5) -> 942.19644 | Z8: =IF($C8*Z$5>(5%*Z$5),(5%*Z$5)*$B8,$C8*Z$5) -> 938.27063 | ... AD8: =IF($C8*AD$5>(5%*AD$5),(5%*AD$5)*$B8,$C8*AD$5) -> 922.73025 | AH8: =IF($C8*AH$5>(5%*AH$5),(5%*AH$5)*$B8,$C8*AH$5) -> 1159.3185 | AI8: =IF($C8*AI$5>(5%*AI$5),(5%*AI$5)*$B8,$C8*AI$5) -> 1153.9083 | AJ8: =IF($C8*AJ$5>(5%*AJ$5),(5%*AJ$5)*$B8,$C8*AJ$5) -> 1148.5234 | AK8: =IF($C8*AK$5>(5%*AK$5),(5%*AK$5)*$B8,$C8*AK$5) -> 1143.1636 | AL8: =IF($C8*AL$5>(5%*AL$5),(5%*AL$5)*$B8,$C8*AL$5) -> 1137.8289 | AM8: =IF($C8*AM$5>(5%*AM$5),(5%*AM$5)*$B8,$C8*AM$5) -> 1132.519 | AN8: =IF($C8*AN$5>(5%*AN$5),(5%*AN$5)*$B8,$C8*AN$5) -> 1127.2339 | AO8: =IF($C8*AO$5>(5%*AO$5),(5%*AO$5)*$B8,$C8*AO$5) -> 1121.9735 | ... AS8: =IF($C8*AS$5>(5%*AS$5),(5%*AS$5)*$B8,$C8*AS$5) -> 1101.1761 | AW8: =IF($C8*AW$5>(5%*AW$5),(5%*AW$5)*$B8,$C8*AW$5) -> 1545.7579 | AX8: =IF($C8*AX$5>(5%*AX$5),(5%*AX$5)*$B8,$C8*AX$5) -> 1536.9987 | AY8: =IF($C8*AY$5>(5%*AY$5),(5%*AY$5)*$B8,$C8*AY$5) -> 1528.289 | AZ8: =IF($C8*AZ$5>(5%*AZ$5),(5%*AZ$5)*$B8,$C8*AZ$5) -> 1519.6287 | BA8: =IF($C8*BA$5>(5%*BA$5),(5%*BA$5)*$B8,$C8*BA$5) -> 1511.0175 | BB8: =IF($C8*BB$5>(5%*BB$5),(5%*BB$5)*$B8,$C8*BB$5) -> 1502.455 | BC8: =IF($C8*BC$5>(5%*BC$5),(5%*BC$5)*$B8,$C8*BC$5) -> 1493.9411 | BD8: =IF($C8*BD$5>(5%*BD$5),(5%*BD$5)*$B8,$C8*BD$5) -> 1485.4755 | ... BH8: =IF($C8*BH$5>(5%*BH$5),(5%*BH$5)*$B8,$C8*BH$5) -> 1452.0898 | BL8: =IF($C8*BL$5>(5%*BL$5),(5%*BL$5)*$B8,$C8*BL$5) -> 1932.1974 | BM8: =IF($C8*BM$5>(5%*BM$5),(5%*BM$5)*$B8,$C8*BM$5) -> 1919.3161 | BN8: =IF($C8*BN$5>(5%*BN$5),(5%*BN$5)*$B8,$C8*BN$5) -> 1906.5207 | BO8: =IF($C8*BO$5>(5%*BO$5),(5%*BO$5)*$B8,$C8*BO$5) -> 1893.8105 | BP8: =IF($C8*BP$5>(5%*BP$5),(5%*BP$5)*$B8,$C8*BP$5) -> 1881.1851 | BQ8: =IF($C8*BQ$5>(5%*BQ$5),(5%*BQ$5)*$B8,$C8*BQ$5) -> 1868.6439 | BR8: =IF($C8*BR$5>(5%*BR$5),(5%*BR$5)*$B8,$C8*BR$5) -> 1856.1863 | BS8: =IF($C8*BS$5>(5%*BS$5),(5%*BS$5)*$B8,$C8*BS$5) -> 1843.8117 | ... BW8: =IF($C8*BW$5>(5%*BW$5),(5%*BW$5)*$B8,$C8*BW$5) -> 1795.1329
A9: 2 | B9: 0.43 | C9: =B9/SUM($B$8:$B$107) -> 0.0075531354 | D9: =IF($C9*D$5>(5%*D$5),(5%*D$5)*$B9,$C9*D$5) -> 188.82839 | E9: =IF($C9*E$5>(5%*E$5),(5%*E$5)*$B9,$C9*E$5) -> 188.27764 | F9: =IF($C9*F$5>(5%*F$5),(5%*F$5)*$B9,$C9*F$5) -> 187.72849 | G9: =IF($C9*G$5>(5%*G$5),(5%*G$5)*$B9,$C9*G$5) -> 187.18095 | H9: =IF($C9*H$5>(5%*H$5),(5%*H$5)*$B9,$C9*H$5) -> 186.63501 | I9: =IF($C9*I$5>(5%*I$5),(5%*I$5)*$B9,$C9*I$5) -> 186.09066 | J9: =IF($C9*J$5>(5%*J$5),(5%*J$5)*$B9,$C9*J$5) -> 185.54789 | K9: =IF($C9*K$5>(5%*K$5),(5%*K$5)*$B9,$C9*K$5) -> 185.00671 | ... O9: =IF($C9*O$5>(5%*O$5),(5%*O$5)*$B9,$C9*O$5) -> 182.85772 | S9: =IF($C9*S$5>(5%*S$5),(5%*S$5)*$B9,$C9*S$5) -> 377.65677 | T9: =IF($C9*T$5>(5%*T$5),(5%*T$5)*$B9,$C9*T$5) -> 376.0832 | U9: =IF($C9*U$5>(5%*U$5),(5%*U$5)*$B9,$C9*U$5) -> 374.51619 | V9: =IF($C9*V$5>(5%*V$5),(5%*V$5)*$B9,$C9*V$5) -> 372.9557 | W9: =IF($C9*W$5>(5%*W$5),(5%*W$5)*$B9,$C9*W$5) -> 371.40172 | X9: =IF($C9*X$5>(5%*X$5),(5%*X$5)*$B9,$C9*X$5) -> 369.85421 | Y9: =IF($C9*Y$5>(5%*Y$5),(5%*Y$5)*$B9,$C9*Y$5) -> 368.31316 | Z9: =IF($C9*Z$5>(5%*Z$5),(5%*Z$5)*$B9,$C9*Z$5) -> 366.77852 | ... AD9: =IF($C9*AD$5>(5%*AD$5),(5%*AD$5)*$B9,$C9*AD$5) -> 360.70364 | AH9: =IF($C9*AH$5>(5%*AH$5),(5%*AH$5)*$B9,$C9*AH$5) -> 453.18813 | AI9: =IF($C9*AI$5>(5%*AI$5),(5%*AI$5)*$B9,$C9*AI$5) -> 451.07325 | AJ9: =IF($C9*AJ$5>(5%*AJ$5),(5%*AJ$5)*$B9,$C9*AJ$5) -> 448.96824 | AK9: =IF($C9*AK$5>(5%*AK$5),(5%*AK$5)*$B9,$C9*AK$5) -> 446.87305 | AL9: =IF($C9*AL$5>(5%*AL$5),(5%*AL$5)*$B9,$C9*AL$5) -> 444.78765 | AM9: =IF($C9*AM$5>(5%*AM$5),(5%*AM$5)*$B9,$C9*AM$5) -> 442.71197 | AN9: =IF($C9*AN$5>(5%*AN$5),(5%*AN$5)*$B9,$C9*AN$5) -> 440.64598 | AO9: =IF($C9*AO$5>(5%*AO$5),(5%*AO$5)*$B9,$C9*AO$5) -> 438.58963 | ... AS9: =IF($C9*AS$5>(5%*AS$5),(5%*AS$5)*$B9,$C9*AS$5) -> 430.45976 | AW9: =IF($C9*AW$5>(5%*AW$5),(5%*AW$5)*$B9,$C9*AW$5) -> 604.25083 | AX9: =IF($C9*AX$5>(5%*AX$5),(5%*AX$5)*$B9,$C9*AX$5) -> 600.82675 | AY9: =IF($C9*AY$5>(5%*AY$5),(5%*AY$5)*$B9,$C9*AY$5) -> 597.42206 | AZ9: =IF($C9*AZ$5>(5%*AZ$5),(5%*AZ$5)*$B9,$C9*AZ$5) -> 594.03667 | BA9: =IF($C9*BA$5>(5%*BA$5),(5%*BA$5)*$B9,$C9*BA$5) -> 590.67046 | BB9: =IF($C9*BB$5>(5%*BB$5),(5%*BB$5)*$B9,$C9*BB$5) -> 587.32333 | BC9: =IF($C9*BC$5>(5%*BC$5),(5%*BC$5)*$B9,$C9*BC$5) -> 583.99516 | BD9: =IF($C9*BD$5>(5%*BD$5),(5%*BD$5)*$B9,$C9*BD$5) -> 580.68586 | ... BH9: =IF($C9*BH$5>(5%*BH$5),(5%*BH$5)*$B9,$C9*BH$5) -> 567.6351 | BL9: =IF($C9*BL$5>(5%*BL$5),(5%*BL$5)*$B9,$C9*BL$5) -> 755.31354 | BM9: =IF($C9*BM$5>(5%*BM$5),(5%*BM$5)*$B9,$C9*BM$5) -> 750.27812 | BN9: =IF($C9*BN$5>(5%*BN$5),(5%*BN$5)*$B9,$C9*BN$5) -> 745.27627 | BO9: =IF($C9*BO$5>(5%*BO$5),(5%*BO$5)*$B9,$C9*BO$5) -> 740.30776 | BP9: =IF($C9*BP$5>(5%*BP$5),(5%*BP$5)*$B9,$C9*BP$5) -> 735.37237 | BQ9: =IF($C9*BQ$5>(5%*BQ$5),(5%*BQ$5)*$B9,$C9*BQ$5) -> 730.46989 | BR9: =IF($C9*BR$5>(5%*BR$5),(5%*BR$5)*$B9,$C9*BR$5) -> 725.60009 | BS9: =IF($C9*BS$5>(5%*BS$5),(5%*BS$5)*$B9,$C9*BS$5) -> 720.76276 | ... BW9: =IF($C9*BW$5>(5%*BW$5),(5%*BW$5)*$B9,$C9*BW$5) -> 701.73377
A10: 3 | B10: 0.44 | C10: =B10/SUM($B$8:$B$107) -> 0.0077287897 | D10: =IF($C10*D$5>(5%*D$5),(5%*D$5)*$B10,$C10*D$5) -> 193.21974 | E10: =IF($C10*E$5>(5%*E$5),(5%*E$5)*$B10,$C10*E$5) -> 192.65619 | F10: =IF($C10*F$5>(5%*F$5),(5%*F$5)*$B10,$C10*F$5) -> 192.09427 | G10: =IF($C10*G$5>(5%*G$5),(5%*G$5)*$B10,$C10*G$5) -> 191.534 | H10: =IF($C10*H$5>(5%*H$5),(5%*H$5)*$B10,$C10*H$5) -> 190.97536 | I10: =IF($C10*I$5>(5%*I$5),(5%*I$5)*$B10,$C10*I$5) -> 190.41834 | J10: =IF($C10*J$5>(5%*J$5),(5%*J$5)*$B10,$C10*J$5) -> 189.86296 | K10: =IF($C10*K$5>(5%*K$5),(5%*K$5)*$B10,$C10*K$5) -> 189.30919 | ... O10: =IF($C10*O$5>(5%*O$5),(5%*O$5)*$B10,$C10*O$5) -> 187.11023 | S10: =IF($C10*S$5>(5%*S$5),(5%*S$5)*$B10,$C10*S$5) -> 386.43949 | T10: =IF($C10*T$5>(5%*T$5),(5%*T$5)*$B10,$C10*T$5) -> 384.82932 | U10: =IF($C10*U$5>(5%*U$5),(5%*U$5)*$B10,$C10*U$5) -> 383.22587 | V10: =IF($C10*V$5>(5%*V$5),(5%*V$5)*$B10,$C10*V$5) -> 381.62909 | W10: =IF($C10*W$5>(5%*W$5),(5%*W$5)*$B10,$C10*W$5) -> 380.03897 | X10: =IF($C10*X$5>(5%*X$5),(5%*X$5)*$B10,$C10*X$5) -> 378.45548 | Y10: =IF($C10*Y$5>(5%*Y$5),(5%*Y$5)*$B10,$C10*Y$5) -> 376.87858 | Z10: =IF($C10*Z$5>(5%*Z$5),(5%*Z$5)*$B10,$C10*Z$5) -> 375.30825 | ... AD10: =IF($C10*AD$5>(5%*AD$5),(5%*AD$5)*$B10,$C10*AD$5) -> 369.0921 | AH10: =IF($C10*AH$5>(5%*AH$5),(5%*AH$5)*$B10,$C10*AH$5) -> 463.72738 | AI10: =IF($C10*AI$5>(5%*AI$5),(5%*AI$5)*$B10,$C10*AI$5) -> 461.56332 | AJ10: =IF($C10*AJ$5>(5%*AJ$5),(5%*AJ$5)*$B10,$C10*AJ$5) -> 459.40936 | AK10: =IF($C10*AK$5>(5%*AK$5),(5%*AK$5)*$B10,$C10*AK$5) -> 457.26545 | AL10: =IF($C10*AL$5>(5%*AL$5),(5%*AL$5)*$B10,$C10*AL$5) -> 455.13155 | AM10: =IF($C10*AM$5>(5%*AM$5),(5%*AM$5)*$B10,$C10*AM$5) -> 453.0076 | AN10: =IF($C10*AN$5>(5%*AN$5),(5%*AN$5)*$B10,$C10*AN$5) -> 450.89356 | AO10: =IF($C10*AO$5>(5%*AO$5),(5%*AO$5)*$B10,$C10*AO$5) -> 448.78939 | ... AS10: =IF($C10*AS$5>(5%*AS$5),(5%*AS$5)*$B10,$C10*AS$5) -> 440.47045 | AW10: =IF($C10*AW$5>(5%*AW$5),(5%*AW$5)*$B10,$C10*AW$5) -> 618.30318 | AX10: =IF($C10*AX$5>(5%*AX$5),(5%*AX$5)*$B10,$C10*AX$5) -> 614.79946 | AY10: =IF($C10*AY$5>(5%*AY$5),(5%*AY$5)*$B10,$C10*AY$5) -> 611.3156 | AZ10: =IF($C10*AZ$5>(5%*AZ$5),(5%*AZ$5)*$B10,$C10*AZ$5) -> 607.85148 | BA10: =IF($C10*BA$5>(5%*BA$5),(5%*BA$5)*$B10,$C10*BA$5) -> 604.40698 | BB10: =IF($C10*BB$5>(5%*BB$5),(5%*BB$5)*$B10,$C10*BB$5) -> 600.98201 | BC10: =IF($C10*BC$5>(5%*BC$5),(5%*BC$5)*$B10,$C10*BC$5) -> 597.57645 | BD10: =IF($C10*BD$5>(5%*BD$5),(5%*BD$5)*$B10,$C10*BD$5) -> 594.19018 | ... BH10: =IF($C10*BH$5>(5%*BH$5),(5%*BH$5)*$B10,$C10*BH$5) -> 580.83592 | BL10: =IF($C10*BL$5>(5%*BL$5),(5%*BL$5)*$B10,$C10*BL$5) -> 772.87897 | BM10: =IF($C10*BM$5>(5%*BM$5),(5%*BM$5)*$B10,$C10*BM$5) -> 767.72645 | BN10: =IF($C10*BN$5>(5%*BN$5),(5%*BN$5)*$B10,$C10*BN$5) -> 762.60827 | BO10: =IF($C10*BO$5>(5%*BO$5),(5%*BO$5)*$B10,$C10*BO$5) -> 757.52422 | BP10: =IF($C10*BP$5>(5%*BP$5),(5%*BP$5)*$B10,$C10*BP$5) -> 752.47405 | BQ10: =IF($C10*BQ$5>(5%*BQ$5),(5%*BQ$5)*$B10,$C10*BQ$5) -> 747.45756 | BR10: =IF($C10*BR$5>(5%*BR$5),(5%*BR$5)*$B10,$C10*BR$5) -> 742.47451 | BS10: =IF($C10*BS$5>(5%*BS$5),(5%*BS$5)*$B10,$C10*BS$5) -> 737.52468 | ... BW10: =IF($C10*BW$5>(5%*BW$5),(5%*BW$5)*$B10,$C10*BW$5) -> 718.05316
A11: 4 | B11: 1.09 | C11: =B11/SUM($B$8:$B$107) -> 0.01914632 | D11: =IF($C11*D$5>(5%*D$5),(5%*D$5)*$B11,$C11*D$5) -> 478.658 | E11: =IF($C11*E$5>(5%*E$5),(5%*E$5)*$B11,$C11*E$5) -> 477.26192 | F11: =IF($C11*F$5>(5%*F$5),(5%*F$5)*$B11,$C11*F$5) -> 475.8699 | G11: =IF($C11*G$5>(5%*G$5),(5%*G$5)*$B11,$C11*G$5) -> 474.48195 | H11: =IF($C11*H$5>(5%*H$5),(5%*H$5)*$B11,$C11*H$5) -> 473.09804 | I11: =IF($C11*I$5>(5%*I$5),(5%*I$5)*$B11,$C11*I$5) -> 471.71817 | J11: =IF($C11*J$5>(5%*J$5),(5%*J$5)*$B11,$C11*J$5) -> 470.34233 | K11: =IF($C11*K$5>(5%*K$5),(5%*K$5)*$B11,$C11*K$5) -> 468.9705 | ... O11: =IF($C11*O$5>(5%*O$5),(5%*O$5)*$B11,$C11*O$5) -> 463.52306 | S11: =IF($C11*S$5>(5%*S$5),(5%*S$5)*$B11,$C11*S$5) -> 957.316 | T11: =IF($C11*T$5>(5%*T$5),(5%*T$5)*$B11,$C11*T$5) -> 953.32719 | U11: =IF($C11*U$5>(5%*U$5),(5%*U$5)*$B11,$C11*U$5) -> 949.35499 | V11: =IF($C11*V$5>(5%*V$5),(5%*V$5)*$B11,$C11*V$5) -> 945.39934 | W11: =IF($C11*W$5>(5%*W$5),(5%*W$5)*$B11,$C11*W$5) -> 941.46018 | X11: =IF($C11*X$5>(5%*X$5),(5%*X$5)*$B11,$C11*X$5) -> 937.53743 | Y11: =IF($C11*Y$5>(5%*Y$5),(5%*Y$5)*$B11,$C11*Y$5) -> 933.63102 | Z11: =IF($C11*Z$5>(5%*Z$5),(5%*Z$5)*$B11,$C11*Z$5) -> 929.74089 | ... AD11: =IF($C11*AD$5>(5%*AD$5),(5%*AD$5)*$B11,$C11*AD$5) -> 914.34179 | AH11: =IF($C11*AH$5>(5%*AH$5),(5%*AH$5)*$B11,$C11*AH$5) -> 1148.7792 | AI11: =IF($C11*AI$5>(5%*AI$5),(5%*AI$5)*$B11,$C11*AI$5) -> 1143.4182 | AJ11: =IF($C11*AJ$5>(5%*AJ$5),(5%*AJ$5)*$B11,$C11*AJ$5) -> 1138.0823 | AK11: =IF($C11*AK$5>(5%*AK$5),(5%*AK$5)*$B11,$C11*AK$5) -> 1132.7712 | AL11: =IF($C11*AL$5>(5%*AL$5),(5%*AL$5)*$B11,$C11*AL$5) -> 1127.485 | AM11: =IF($C11*AM$5>(5%*AM$5),(5%*AM$5)*$B11,$C11*AM$5) -> 1122.2234 | AN11: =IF($C11*AN$5>(5%*AN$5),(5%*AN$5)*$B11,$C11*AN$5) -> 1116.9863 | AO11: =IF($C11*AO$5>(5%*AO$5),(5%*AO$5)*$B11,$C11*AO$5) -> 1111.7737 | ... AS11: =IF($C11*AS$5>(5%*AS$5),(5%*AS$5)*$B11,$C11*AS$5) -> 1091.1654 | AW11: =IF($C11*AW$5>(5%*AW$5),(5%*AW$5)*$B11,$C11*AW$5) -> 1531.7056 | AX11: =IF($C11*AX$5>(5%*AX$5),(5%*AX$5)*$B11,$C11*AX$5) -> 1523.0259 | AY11: =IF($C11*AY$5>(5%*AY$5),(5%*AY$5)*$B11,$C11*AY$5) -> 1514.3955 | AZ11: =IF($C11*AZ$5>(5%*AZ$5),(5%*AZ$5)*$B11,$C11*AZ$5) -> 1505.8139 | BA11: =IF($C11*BA$5>(5%*BA$5),(5%*BA$5)*$B11,$C11*BA$5) -> 1497.2809 | BB11: =IF($C11*BB$5>(5%*BB$5),(5%*BB$5)*$B11,$C11*BB$5) -> 1488.7963 | BC11: =IF($C11*BC$5>(5%*BC$5),(5%*BC$5)*$B11,$C11*BC$5) -> 1480.3598 | BD11: =IF($C11*BD$5>(5%*BD$5),(5%*BD$5)*$B11,$C11*BD$5) -> 1471.9711 | ... BH11: =IF($C11*BH$5>(5%*BH$5),(5%*BH$5)*$B11,$C11*BH$5) -> 1438.889 | BL11: =IF($C11*BL$5>(5%*BL$5),(5%*BL$5)*$B11,$C11*BL$5) -> 1914.632 | BM11: =IF($C11*BM$5>(5%*BM$5),(5%*BM$5)*$B11,$C11*BM$5) -> 1901.8678 | BN11: =IF($C11*BN$5>(5%*BN$5),(5%*BN$5)*$B11,$C11*BN$5) -> 1889.1887 | BO11: =IF($C11*BO$5>(5%*BO$5),(5%*BO$5)*$B11,$C11*BO$5) -> 1876.5941 | BP11: =IF($C11*BP$5>(5%*BP$5),(5%*BP$5)*$B11,$C11*BP$5) -> 1864.0835 | BQ11: =IF($C11*BQ$5>(5%*BQ$5),(5%*BQ$5)*$B11,$C11*BQ$5) -> 1851.6562 | BR11: =IF($C11*BR$5>(5%*BR$5),(5%*BR$5)*$B11,$C11*BR$5) -> 1839.3119 | BS11: =IF($C11*BS$5>(5%*BS$5),(5%*BS$5)*$B11,$C11*BS$5) -> 1827.0498 | ... BW11: =IF($C11*BW$5>(5%*BW$5),(5%*BW$5)*$B11,$C11*BW$5) -> 1778.8135
A12: 5 | B12: 0.2 | C12: =B12/SUM($B$8:$B$107) -> 0.0035130862 | D12: =IF($C12*D$5>(5%*D$5),(5%*D$5)*$B12,$C12*D$5) -> 87.827156 | E12: =IF($C12*E$5>(5%*E$5),(5%*E$5)*$B12,$C12*E$5) -> 87.570994 | F12: =IF($C12*F$5>(5%*F$5),(5%*F$5)*$B12,$C12*F$5) -> 87.315578 | G12: =IF($C12*G$5>(5%*G$5),(5%*G$5)*$B12,$C12*G$5) -> 87.060908 | H12: =IF($C12*H$5>(5%*H$5),(5%*H$5)*$B12,$C12*H$5) -> 86.80698 | I12: =IF($C12*I$5>(5%*I$5),(5%*I$5)*$B12,$C12*I$5) -> 86.553793 | J12: =IF($C12*J$5>(5%*J$5),(5%*J$5)*$B12,$C12*J$5) -> 86.301345 | K12: =IF($C12*K$5>(5%*K$5),(5%*K$5)*$B12,$C12*K$5) -> 86.049632 | ... O12: =IF($C12*O$5>(5%*O$5),(5%*O$5)*$B12,$C12*O$5) -> 85.050103 | S12: =IF($C12*S$5>(5%*S$5),(5%*S$5)*$B12,$C12*S$5) -> 175.65431 | T12: =IF($C12*T$5>(5%*T$5),(5%*T$5)*$B12,$C12*T$5) -> 174.92242 | U12: =IF($C12*U$5>(5%*U$5),(5%*U$5)*$B12,$C12*U$5) -> 174.19358 | V12: =IF($C12*V$5>(5%*V$5),(5%*V$5)*$B12,$C12*V$5) -> 173.46777 | W12: =IF($C12*W$5>(5%*W$5),(5%*W$5)*$B12,$C12*W$5) -> 172.74499 | X12: =IF($C12*X$5>(5%*X$5),(5%*X$5)*$B12,$C12*X$5) -> 172.02522 | Y12: =IF($C12*Y$5>(5%*Y$5),(5%*Y$5)*$B12,$C12*Y$5) -> 171.30844 | Z12: =IF($C12*Z$5>(5%*Z$5),(5%*Z$5)*$B12,$C12*Z$5) -> 170.59466 | ... AD12: =IF($C12*AD$5>(5%*AD$5),(5%*AD$5)*$B12,$C12*AD$5) -> 167.76914 | AH12: =IF($C12*AH$5>(5%*AH$5),(5%*AH$5)*$B12,$C12*AH$5) -> 210.78517 | AI12: =IF($C12*AI$5>(5%*AI$5),(5%*AI$5)*$B12,$C12*AI$5) -> 209.80151 | AJ12: =IF($C12*AJ$5>(5%*AJ$5),(5%*AJ$5)*$B12,$C12*AJ$5) -> 208.82244 | AK12: =IF($C12*AK$5>(5%*AK$5),(5%*AK$5)*$B12,$C12*AK$5) -> 207.84793 | AL12: =IF($C12*AL$5>(5%*AL$5),(5%*AL$5)*$B12,$C12*AL$5) -> 206.87798 | AM12: =IF($C12*AM$5>(5%*AM$5),(5%*AM$5)*$B12,$C12*AM$5) -> 205.91254 | AN12: =IF($C12*AN$5>(5%*AN$5),(5%*AN$5)*$B12,$C12*AN$5) -> 204.95162 | AO12: =IF($C12*AO$5>(5%*AO$5),(5%*AO$5)*$B12,$C12*AO$5) -> 203.99518 | ... AS12: =IF($C12*AS$5>(5%*AS$5),(5%*AS$5)*$B12,$C12*AS$5) -> 200.21384 | AW12: =IF($C12*AW$5>(5%*AW$5),(5%*AW$5)*$B12,$C12*AW$5) -> 281.0469 | AX12: =IF($C12*AX$5>(5%*AX$5),(5%*AX$5)*$B12,$C12*AX$5) -> 279.4543 | AY12: =IF($C12*AY$5>(5%*AY$5),(5%*AY$5)*$B12,$C12*AY$5) -> 277.87073 | AZ12: =IF($C12*AZ$5>(5%*AZ$5),(5%*AZ$5)*$B12,$C12*AZ$5) -> 276.29613 | BA12: =IF($C12*BA$5>(5%*BA$5),(5%*BA$5)*$B12,$C12*BA$5) -> 274.73045 | BB12: =IF($C12*BB$5>(5%*BB$5),(5%*BB$5)*$B12,$C12*BB$5) -> 273.17364 | BC12: =IF($C12*BC$5>(5%*BC$5),(5%*BC$5)*$B12,$C12*BC$5) -> 271.62566 | BD12: =IF($C12*BD$5>(5%*BD$5),(5%*BD$5)*$B12,$C12*BD$5) -> 270.08645 | ... BH12: =IF($C12*BH$5>(5%*BH$5),(5%*BH$5)*$B12,$C12*BH$5) -> 264.01633 | BL12: =IF($C12*BL$5>(5%*BL$5),(5%*BL$5)*$B12,$C12*BL$5) -> 351.30862 | BM12: =IF($C12*BM$5>(5%*BM$5),(5%*BM$5)*$B12,$C12*BM$5) -> 348.96657 | BN12: =IF($C12*BN$5>(5%*BN$5),(5%*BN$5)*$B12,$C12*BN$5) -> 346.64012 | BO12: =IF($C12*BO$5>(5%*BO$5),(5%*BO$5)*$B12,$C12*BO$5) -> 344.32919 | BP12: =IF($C12*BP$5>(5%*BP$5),(5%*BP$5)*$B12,$C12*BP$5) -> 342.03366 | BQ12: =IF($C12*BQ$5>(5%*BQ$5),(5%*BQ$5)*$B12,$C12*BQ$5) -> 339.75344 | BR12: =IF($C12*BR$5>(5%*BR$5),(5%*BR$5)*$B12,$C12*BR$5) -> 337.48841 | BS12: =IF($C12*BS$5>(5%*BS$5),(5%*BS$5)*$B12,$C12*BS$5) -> 335.23849 | ... BW12: =IF($C12*BW$5>(5%*BW$5),(5%*BW$5)*$B12,$C12*BW$5) -> 326.3878
A13: 6 | B13: 0.3 | C13: =B13/SUM($B$8:$B$107) -> 0.0052696294 | D13: =IF($C13*D$5>(5%*D$5),(5%*D$5)*$B13,$C13*D$5) -> 131.74073 | E13: =IF($C13*E$5>(5%*E$5),(5%*E$5)*$B13,$C13*E$5) -> 131.35649 | F13: =IF($C13*F$5>(5%*F$5),(5%*F$5)*$B13,$C13*F$5) -> 130.97337 | G13: =IF($C13*G$5>(5%*G$5),(5%*G$5)*$B13,$C13*G$5) -> 130.59136 | H13: =IF($C13*H$5>(5%*H$5),(5%*H$5)*$B13,$C13*H$5) -> 130.21047 | I13: =IF($C13*I$5>(5%*I$5),(5%*I$5)*$B13,$C13*I$5) -> 129.83069 | J13: =IF($C13*J$5>(5%*J$5),(5%*J$5)*$B13,$C13*J$5) -> 129.45202 | K13: =IF($C13*K$5>(5%*K$5),(5%*K$5)*$B13,$C13*K$5) -> 129.07445 | ... O13: =IF($C13*O$5>(5%*O$5),(5%*O$5)*$B13,$C13*O$5) -> 127.57516 | S13: =IF($C13*S$5>(5%*S$5),(5%*S$5)*$B13,$C13*S$5) -> 263.48147 | T13: =IF($C13*T$5>(5%*T$5),(5%*T$5)*$B13,$C13*T$5) -> 262.38363 | U13: =IF($C13*U$5>(5%*U$5),(5%*U$5)*$B13,$C13*U$5) -> 261.29036 | V13: =IF($C13*V$5>(5%*V$5),(5%*V$5)*$B13,$C13*V$5) -> 260.20165 | W13: =IF($C13*W$5>(5%*W$5),(5%*W$5)*$B13,$C13*W$5) -> 259.11748 | X13: =IF($C13*X$5>(5%*X$5),(5%*X$5)*$B13,$C13*X$5) -> 258.03782 | Y13: =IF($C13*Y$5>(5%*Y$5),(5%*Y$5)*$B13,$C13*Y$5) -> 256.96267 | Z13: =IF($C13*Z$5>(5%*Z$5),(5%*Z$5)*$B13,$C13*Z$5) -> 255.89199 | ... AD13: =IF($C13*AD$5>(5%*AD$5),(5%*AD$5)*$B13,$C13*AD$5) -> 251.6537 | AH13: =IF($C13*AH$5>(5%*AH$5),(5%*AH$5)*$B13,$C13*AH$5) -> 316.17776 | AI13: =IF($C13*AI$5>(5%*AI$5),(5%*AI$5)*$B13,$C13*AI$5) -> 314.70227 | AJ13: =IF($C13*AJ$5>(5%*AJ$5),(5%*AJ$5)*$B13,$C13*AJ$5) -> 313.23366 | AK13: =IF($C13*AK$5>(5%*AK$5),(5%*AK$5)*$B13,$C13*AK$5) -> 311.7719 | AL13: =IF($C13*AL$5>(5%*AL$5),(5%*AL$5)*$B13,$C13*AL$5) -> 310.31696 | AM13: =IF($C13*AM$5>(5%*AM$5),(5%*AM$5)*$B13,$C13*AM$5) -> 308.86882 | AN13: =IF($C13*AN$5>(5%*AN$5),(5%*AN$5)*$B13,$C13*AN$5) -> 307.42743 | AO13: =IF($C13*AO$5>(5%*AO$5),(5%*AO$5)*$B13,$C13*AO$5) -> 305.99277 | ... AS13: =IF($C13*AS$5>(5%*AS$5),(5%*AS$5)*$B13,$C13*AS$5) -> 300.32076 | AW13: =IF($C13*AW$5>(5%*AW$5),(5%*AW$5)*$B13,$C13*AW$5) -> 421.57035 | AX13: =IF($C13*AX$5>(5%*AX$5),(5%*AX$5)*$B13,$C13*AX$5) -> 419.18145 | AY13: =IF($C13*AY$5>(5%*AY$5),(5%*AY$5)*$B13,$C13*AY$5) -> 416.80609 | AZ13: =IF($C13*AZ$5>(5%*AZ$5),(5%*AZ$5)*$B13,$C13*AZ$5) -> 414.44419 | BA13: =IF($C13*BA$5>(5%*BA$5),(5%*BA$5)*$B13,$C13*BA$5) -> 412.09567 | BB13: =IF($C13*BB$5>(5%*BB$5),(5%*BB$5)*$B13,$C13*BB$5) -> 409.76046 | BC13: =IF($C13*BC$5>(5%*BC$5),(5%*BC$5)*$B13,$C13*BC$5) -> 407.43849 | BD13: =IF($C13*BD$5>(5%*BD$5),(5%*BD$5)*$B13,$C13*BD$5) -> 405.12967 | ... BH13: =IF($C13*BH$5>(5%*BH$5),(5%*BH$5)*$B13,$C13*BH$5) -> 396.02449 | BL13: =IF($C13*BL$5>(5%*BL$5),(5%*BL$5)*$B13,$C13*BL$5) -> 526.96294 | BM13: =IF($C13*BM$5>(5%*BM$5),(5%*BM$5)*$B13,$C13*BM$5) -> 523.44985 | BN13: =IF($C13*BN$5>(5%*BN$5),(5%*BN$5)*$B13,$C13*BN$5) -> 519.96019 | BO13: =IF($C13*BO$5>(5%*BO$5),(5%*BO$5)*$B13,$C13*BO$5) -> 516.49378 | BP13: =IF($C13*BP$5>(5%*BP$5),(5%*BP$5)*$B13,$C13*BP$5) -> 513.05049 | BQ13: =IF($C13*BQ$5>(5%*BQ$5),(5%*BQ$5)*$B13,$C13*BQ$5) -> 509.63016 | BR13: =IF($C13*BR$5>(5%*BR$5),(5%*BR$5)*$B13,$C13*BR$5) -> 506.23262 | BS13: =IF($C13*BS$5>(5%*BS$5),(5%*BS$5)*$B13,$C13*BS$5) -> 502.85774 | ... BW13: =IF($C13*BW$5>(5%*BW$5),(5%*BW$5)*$B13,$C13*BW$5) -> 489.5817
A14: 7 | B14: 0.39 | C14: =B14/SUM($B$8:$B$107) -> 0.0068505182 | D14: =IF($C14*D$5>(5%*D$5),(5%*D$5)*$B14,$C14*D$5) -> 171.26295 | E14: =IF($C14*E$5>(5%*E$5),(5%*E$5)*$B14,$C14*E$5) -> 170.76344 | F14: =IF($C14*F$5>(5%*F$5),(5%*F$5)*$B14,$C14*F$5) -> 170.26538 | G14: =IF($C14*G$5>(5%*G$5),(5%*G$5)*$B14,$C14*G$5) -> 169.76877 | H14: =IF($C14*H$5>(5%*H$5),(5%*H$5)*$B14,$C14*H$5) -> 169.27361 | I14: =IF($C14*I$5>(5%*I$5),(5%*I$5)*$B14,$C14*I$5) -> 168.7799 | J14: =IF($C14*J$5>(5%*J$5),(5%*J$5)*$B14,$C14*J$5) -> 168.28762 | K14: =IF($C14*K$5>(5%*K$5),(5%*K$5)*$B14,$C14*K$5) -> 167.79678 | ... O14: =IF($C14*O$5>(5%*O$5),(5%*O$5)*$B14,$C14*O$5) -> 165.8477 | S14: =IF($C14*S$5>(5%*S$5),(5%*S$5)*$B14,$C14*S$5) -> 342.52591 | T14: =IF($C14*T$5>(5%*T$5),(5%*T$5)*$B14,$C14*T$5) -> 341.09872 | U14: =IF($C14*U$5>(5%*U$5),(5%*U$5)*$B14,$C14*U$5) -> 339.67747 | V14: =IF($C14*V$5>(5%*V$5),(5%*V$5)*$B14,$C14*V$5) -> 338.26215 | W14: =IF($C14*W$5>(5%*W$5),(5%*W$5)*$B14,$C14*W$5) -> 336.85272 | X14: =IF($C14*X$5>(5%*X$5),(5%*X$5)*$B14,$C14*X$5) -> 335.44917 | Y14: =IF($C14*Y$5>(5%*Y$5),(5%*Y$5)*$B14,$C14*Y$5) -> 334.05147 | Z14: =IF($C14*Z$5>(5%*Z$5),(5%*Z$5)*$B14,$C14*Z$5) -> 332.65959 | ... AD14: =IF($C14*AD$5>(5%*AD$5),(5%*AD$5)*$B14,$C14*AD$5) -> 327.14982 | AH14: =IF($C14*AH$5>(5%*AH$5),(5%*AH$5)*$B14,$C14*AH$5) -> 411.03109 | AI14: =IF($C14*AI$5>(5%*AI$5),(5%*AI$5)*$B14,$C14*AI$5) -> 409.11295 | AJ14: =IF($C14*AJ$5>(5%*AJ$5),(5%*AJ$5)*$B14,$C14*AJ$5) -> 407.20375 | AK14: =IF($C14*AK$5>(5%*AK$5),(5%*AK$5)*$B14,$C14*AK$5) -> 405.30347 | AL14: =IF($C14*AL$5>(5%*AL$5),(5%*AL$5)*$B14,$C14*AL$5) -> 403.41205 | AM14: =IF($C14*AM$5>(5%*AM$5),(5%*AM$5)*$B14,$C14*AM$5) -> 401.52946 | AN14: =IF($C14*AN$5>(5%*AN$5),(5%*AN$5)*$B14,$C14*AN$5) -> 399.65566 | AO14: =IF($C14*AO$5>(5%*AO$5),(5%*AO$5)*$B14,$C14*AO$5) -> 397.7906 | ... AS14: =IF($C14*AS$5>(5%*AS$5),(5%*AS$5)*$B14,$C14*AS$5) -> 390.41699 | AW14: =IF($C14*AW$5>(5%*AW$5),(5%*AW$5)*$B14,$C14*AW$5) -> 548.04145 | AX14: =IF($C14*AX$5>(5%*AX$5),(5%*AX$5)*$B14,$C14*AX$5) -> 544.93589 | AY14: =IF($C14*AY$5>(5%*AY$5),(5%*AY$5)*$B14,$C14*AY$5) -> 541.84792 | AZ14: =IF($C14*AZ$5>(5%*AZ$5),(5%*AZ$5)*$B14,$C14*AZ$5) -> 538.77744 | BA14: =IF($C14*BA$5>(5%*BA$5),(5%*BA$5)*$B14,$C14*BA$5) -> 535.72437 | BB14: =IF($C14*BB$5>(5%*BB$5),(5%*BB$5)*$B14,$C14*BB$5) -> 532.6886 | BC14: =IF($C14*BC$5>(5%*BC$5),(5%*BC$5)*$B14,$C14*BC$5) -> 529.67003 | BD14: =IF($C14*BD$5>(5%*BD$5),(5%*BD$5)*$B14,$C14*BD$5) -> 526.66857 | ... BH14: =IF($C14*BH$5>(5%*BH$5),(5%*BH$5)*$B14,$C14*BH$5) -> 514.83184 | BL14: =IF($C14*BL$5>(5%*BL$5),(5%*BL$5)*$B14,$C14*BL$5) -> 685.05182 | BM14: =IF($C14*BM$5>(5%*BM$5),(5%*BM$5)*$B14,$C14*BM$5) -> 680.48481 | BN14: =IF($C14*BN$5>(5%*BN$5),(5%*BN$5)*$B14,$C14*BN$5) -> 675.94824 | BO14: =IF($C14*BO$5>(5%*BO$5),(5%*BO$5)*$B14,$C14*BO$5) -> 671.44192 | BP14: =IF($C14*BP$5>(5%*BP$5),(5%*BP$5)*$B14,$C14*BP$5) -> 666.96564 | BQ14: =IF($C14*BQ$5>(5%*BQ$5),(5%*BQ$5)*$B14,$C14*BQ$5) -> 662.5192 | BR14: =IF($C14*BR$5>(5%*BR$5),(5%*BR$5)*$B14,$C14*BR$5) -> 658.10241 | BS14: =IF($C14*BS$5>(5%*BS$5),(5%*BS$5)*$B14,$C14*BS$5) -> 653.71506 | ... BW14: =IF($C14*BW$5>(5%*BW$5),(5%*BW$5)*$B14,$C14*BW$5) -> 636.45621
A15: 8 | B15: 0.53 | C15: =B15/SUM($B$8:$B$107) -> 0.0093096786 | D15: =IF($C15*D$5>(5%*D$5),(5%*D$5)*$B15,$C15*D$5) -> 232.74196 | E15: =IF($C15*E$5>(5%*E$5),(5%*E$5)*$B15,$C15*E$5) -> 232.06313 | F15: =IF($C15*F$5>(5%*F$5),(5%*F$5)*$B15,$C15*F$5) -> 231.38628 | G15: =IF($C15*G$5>(5%*G$5),(5%*G$5)*$B15,$C15*G$5) -> 230.71141 | H15: =IF($C15*H$5>(5%*H$5),(5%*H$5)*$B15,$C15*H$5) -> 230.0385 | I15: =IF($C15*I$5>(5%*I$5),(5%*I$5)*$B15,$C15*I$5) -> 229.36755 | J15: =IF($C15*J$5>(5%*J$5),(5%*J$5)*$B15,$C15*J$5) -> 228.69856 | K15: =IF($C15*K$5>(5%*K$5),(5%*K$5)*$B15,$C15*K$5) -> 228.03153 | ... O15: =IF($C15*O$5>(5%*O$5),(5%*O$5)*$B15,$C15*O$5) -> 225.38277 | S15: =IF($C15*S$5>(5%*S$5),(5%*S$5)*$B15,$C15*S$5) -> 465.48393 | T15: =IF($C15*T$5>(5%*T$5),(5%*T$5)*$B15,$C15*T$5) -> 463.54441 | U15: =IF($C15*U$5>(5%*U$5),(5%*U$5)*$B15,$C15*U$5) -> 461.61298 | V15: =IF($C15*V$5>(5%*V$5),(5%*V$5)*$B15,$C15*V$5) -> 459.68959 | W15: =IF($C15*W$5>(5%*W$5),(5%*W$5)*$B15,$C15*W$5) -> 457.77422 | X15: =IF($C15*X$5>(5%*X$5),(5%*X$5)*$B15,$C15*X$5) -> 455.86682 | Y15: =IF($C15*Y$5>(5%*Y$5),(5%*Y$5)*$B15,$C15*Y$5) -> 453.96738 | Z15: =IF($C15*Z$5>(5%*Z$5),(5%*Z$5)*$B15,$C15*Z$5) -> 452.07585 | ... AD15: =IF($C15*AD$5>(5%*AD$5),(5%*AD$5)*$B15,$C15*AD$5) -> 444.58821 | AH15: =IF($C15*AH$5>(5%*AH$5),(5%*AH$5)*$B15,$C15*AH$5) -> 558.58071 | AI15: =IF($C15*AI$5>(5%*AI$5),(5%*AI$5)*$B15,$C15*AI$5) -> 555.974 | AJ15: =IF($C15*AJ$5>(5%*AJ$5),(5%*AJ$5)*$B15,$C15*AJ$5) -> 553.37946 | AK15: =IF($C15*AK$5>(5%*AK$5),(5%*AK$5)*$B15,$C15*AK$5) -> 550.79702 | AL15: =IF($C15*AL$5>(5%*AL$5),(5%*AL$5)*$B15,$C15*AL$5) -> 548.22663 | AM15: =IF($C15*AM$5>(5%*AM$5),(5%*AM$5)*$B15,$C15*AM$5) -> 545.66824 | AN15: =IF($C15*AN$5>(5%*AN$5),(5%*AN$5)*$B15,$C15*AN$5) -> 543.12179 | AO15: =IF($C15*AO$5>(5%*AO$5),(5%*AO$5)*$B15,$C15*AO$5) -> 540.58722 | ... AS15: =IF($C15*AS$5>(5%*AS$5),(5%*AS$5)*$B15,$C15*AS$5) -> 530.56668 | AW15: =IF($C15*AW$5>(5%*AW$5),(5%*AW$5)*$B15,$C15*AW$5) -> 744.77428 | AX15: =IF($C15*AX$5>(5%*AX$5),(5%*AX$5)*$B15,$C15*AX$5) -> 740.5539 | AY15: =IF($C15*AY$5>(5%*AY$5),(5%*AY$5)*$B15,$C15*AY$5) -> 736.35742 | AZ15: =IF($C15*AZ$5>(5%*AZ$5),(5%*AZ$5)*$B15,$C15*AZ$5) -> 732.18473 | BA15: =IF($C15*BA$5>(5%*BA$5),(5%*BA$5)*$B15,$C15*BA$5) -> 728.03569 | BB15: =IF($C15*BB$5>(5%*BB$5),(5%*BB$5)*$B15,$C15*BB$5) -> 723.91015 | BC15: =IF($C15*BC$5>(5%*BC$5),(5%*BC$5)*$B15,$C15*BC$5) -> 719.80799 | BD15: =IF($C15*BD$5>(5%*BD$5),(5%*BD$5)*$B15,$C15*BD$5) -> 715.72908 | ... BH15: =IF($C15*BH$5>(5%*BH$5),(5%*BH$5)*$B15,$C15*BH$5) -> 699.64327 | BL15: =IF($C15*BL$5>(5%*BL$5),(5%*BL$5)*$B15,$C15*BL$5) -> 930.96786 | BM15: =IF($C15*BM$5>(5%*BM$5),(5%*BM$5)*$B15,$C15*BM$5) -> 924.7614 | BN15: =IF($C15*BN$5>(5%*BN$5),(5%*BN$5)*$B15,$C15*BN$5) -> 918.59633 | BO15: =IF($C15*BO$5>(5%*BO$5),(5%*BO$5)*$B15,$C15*BO$5) -> 912.47235 | BP15: =IF($C15*BP$5>(5%*BP$5),(5%*BP$5)*$B15,$C15*BP$5) -> 906.3892 | BQ15: =IF($C15*BQ$5>(5%*BQ$5),(5%*BQ$5)*$B15,$C15*BQ$5) -> 900.34661 | BR15: =IF($C15*BR$5>(5%*BR$5),(5%*BR$5)*$B15,$C15*BR$5) -> 894.3443 | BS15: =IF($C15*BS$5>(5%*BS$5),(5%*BS$5)*$B15,$C15*BS$5) -> 888.382 | ... BW15: =IF($C15*BW$5>(5%*BW$5),(5%*BW$5)*$B15,$C15*BW$5) -> 864.92767
A16: 9 | B16: 1 | C16: =B16/SUM($B$8:$B$107) -> 0.017565431 | D16: =IF($C16*D$5>(5%*D$5),(5%*D$5)*$B16,$C16*D$5) -> 439.13578 | E16: =IF($C16*E$5>(5%*E$5),(5%*E$5)*$B16,$C16*E$5) -> 437.85497 | F16: =IF($C16*F$5>(5%*F$5),(5%*F$5)*$B16,$C16*F$5) -> 436.57789 | G16: =IF($C16*G$5>(5%*G$5),(5%*G$5)*$B16,$C16*G$5) -> 435.30454 | H16: =IF($C16*H$5>(5%*H$5),(5%*H$5)*$B16,$C16*H$5) -> 434.0349 | I16: =IF($C16*I$5>(5%*I$5),(5%*I$5)*$B16,$C16*I$5) -> 432.76897 | J16: =IF($C16*J$5>(5%*J$5),(5%*J$5)*$B16,$C16*J$5) -> 431.50672 | K16: =IF($C16*K$5>(5%*K$5),(5%*K$5)*$B16,$C16*K$5) -> 430.24816 | ... O16: =IF($C16*O$5>(5%*O$5),(5%*O$5)*$B16,$C16*O$5) -> 425.25052 | S16: =IF($C16*S$5>(5%*S$5),(5%*S$5)*$B16,$C16*S$5) -> 878.27156 | T16: =IF($C16*T$5>(5%*T$5),(5%*T$5)*$B16,$C16*T$5) -> 874.6121 | U16: =IF($C16*U$5>(5%*U$5),(5%*U$5)*$B16,$C16*U$5) -> 870.96788 | V16: =IF($C16*V$5>(5%*V$5),(5%*V$5)*$B16,$C16*V$5) -> 867.33885 | W16: =IF($C16*W$5>(5%*W$5),(5%*W$5)*$B16,$C16*W$5) -> 863.72493 | X16: =IF($C16*X$5>(5%*X$5),(5%*X$5)*$B16,$C16*X$5) -> 860.12608 | Y16: =IF($C16*Y$5>(5%*Y$5),(5%*Y$5)*$B16,$C16*Y$5) -> 856.54222 | Z16: =IF($C16*Z$5>(5%*Z$5),(5%*Z$5)*$B16,$C16*Z$5) -> 852.9733 | ... AD16: =IF($C16*AD$5>(5%*AD$5),(5%*AD$5)*$B16,$C16*AD$5) -> 838.84568 | AH16: =IF($C16*AH$5>(5%*AH$5),(5%*AH$5)*$B16,$C16*AH$5) -> 1053.9259 | AI16: =IF($C16*AI$5>(5%*AI$5),(5%*AI$5)*$B16,$C16*AI$5) -> 1049.0076 | AJ16: =IF($C16*AJ$5>(5%*AJ$5),(5%*AJ$5)*$B16,$C16*AJ$5) -> 1044.1122 | AK16: =IF($C16*AK$5>(5%*AK$5),(5%*AK$5)*$B16,$C16*AK$5) -> 1039.2397 | AL16: =IF($C16*AL$5>(5%*AL$5),(5%*AL$5)*$B16,$C16*AL$5) -> 1034.3899 | AM16: =IF($C16*AM$5>(5%*AM$5),(5%*AM$5)*$B16,$C16*AM$5) -> 1029.5627 | AN16: =IF($C16*AN$5>(5%*AN$5),(5%*AN$5)*$B16,$C16*AN$5) -> 1024.7581 | AO16: =IF($C16*AO$5>(5%*AO$5),(5%*AO$5)*$B16,$C16*AO$5) -> 1019.9759 | ... AS16: =IF($C16*AS$5>(5%*AS$5),(5%*AS$5)*$B16,$C16*AS$5) -> 1001.0692 | AW16: =IF($C16*AW$5>(5%*AW$5),(5%*AW$5)*$B16,$C16*AW$5) -> 1405.2345 | AX16: =IF($C16*AX$5>(5%*AX$5),(5%*AX$5)*$B16,$C16*AX$5) -> 1397.2715 | AY16: =IF($C16*AY$5>(5%*AY$5),(5%*AY$5)*$B16,$C16*AY$5) -> 1389.3536 | AZ16: =IF($C16*AZ$5>(5%*AZ$5),(5%*AZ$5)*$B16,$C16*AZ$5) -> 1381.4806 | BA16: =IF($C16*BA$5>(5%*BA$5),(5%*BA$5)*$B16,$C16*BA$5) -> 1373.6522 | BB16: =IF($C16*BB$5>(5%*BB$5),(5%*BB$5)*$B16,$C16*BB$5) -> 1365.8682 | BC16: =IF($C16*BC$5>(5%*BC$5),(5%*BC$5)*$B16,$C16*BC$5) -> 1358.1283 | BD16: =IF($C16*BD$5>(5%*BD$5),(5%*BD$5)*$B16,$C16*BD$5) -> 1350.4322 | ... BH16: =IF($C16*BH$5>(5%*BH$5),(5%*BH$5)*$B16,$C16*BH$5) -> 1320.0816 | BL16: =IF($C16*BL$5>(5%*BL$5),(5%*BL$5)*$B16,$C16*BL$5) -> 1756.5431 | BM16: =IF($C16*BM$5>(5%*BM$5),(5%*BM$5)*$B16,$C16*BM$5) -> 1744.8328 | BN16: =IF($C16*BN$5>(5%*BN$5),(5%*BN$5)*$B16,$C16*BN$5) -> 1733.2006 | BO16: =IF($C16*BO$5>(5%*BO$5),(5%*BO$5)*$B16,$C16*BO$5) -> 1721.6459 | BP16: =IF($C16*BP$5>(5%*BP$5),(5%*BP$5)*$B16,$C16*BP$5) -> 1710.1683 | BQ16: =IF($C16*BQ$5>(5%*BQ$5),(5%*BQ$5)*$B16,$C16*BQ$5) -> 1698.7672 | BR16: =IF($C16*BR$5>(5%*BR$5),(5%*BR$5)*$B16,$C16*BR$5) -> 1687.4421 | BS16: =IF($C16*BS$5>(5%*BS$5),(5%*BS$5)*$B16,$C16*BS$5) -> 1676.1925 | ... BW16: =IF($C16*BW$5>(5%*BW$5),(5%*BW$5)*$B16,$C16*BW$5) -> 1631.939
A17: 10 | B17: 0.32 | C17: =B17/SUM($B$8:$B$107) -> 0.005620938 | D17: =IF($C17*D$5>(5%*D$5),(5%*D$5)*$B17,$C17*D$5) -> 140.52345 | E17: =IF($C17*E$5>(5%*E$5),(5%*E$5)*$B17,$C17*E$5) -> 140.11359 | F17: =IF($C17*F$5>(5%*F$5),(5%*F$5)*$B17,$C17*F$5) -> 139.70493 | G17: =IF($C17*G$5>(5%*G$5),(5%*G$5)*$B17,$C17*G$5) -> 139.29745 | H17: =IF($C17*H$5>(5%*H$5),(5%*H$5)*$B17,$C17*H$5) -> 138.89117 | I17: =IF($C17*I$5>(5%*I$5),(5%*I$5)*$B17,$C17*I$5) -> 138.48607 | J17: =IF($C17*J$5>(5%*J$5),(5%*J$5)*$B17,$C17*J$5) -> 138.08215 | K17: =IF($C17*K$5>(5%*K$5),(5%*K$5)*$B17,$C17*K$5) -> 137.67941 | ... O17: =IF($C17*O$5>(5%*O$5),(5%*O$5)*$B17,$C17*O$5) -> 136.08017 | S17: =IF($C17*S$5>(5%*S$5),(5%*S$5)*$B17,$C17*S$5) -> 281.0469 | T17: =IF($C17*T$5>(5%*T$5),(5%*T$5)*$B17,$C17*T$5) -> 279.87587 | U17: =IF($C17*U$5>(5%*U$5),(5%*U$5)*$B17,$C17*U$5) -> 278.70972 | V17: =IF($C17*V$5>(5%*V$5),(5%*V$5)*$B17,$C17*V$5) -> 277.54843 | W17: =IF($C17*W$5>(5%*W$5),(5%*W$5)*$B17,$C17*W$5) -> 276.39198 | X17: =IF($C17*X$5>(5%*X$5),(5%*X$5)*$B17,$C17*X$5) -> 275.24035 | Y17: =IF($C17*Y$5>(5%*Y$5),(5%*Y$5)*$B17,$C17*Y$5) -> 274.09351 | Z17: =IF($C17*Z$5>(5%*Z$5),(5%*Z$5)*$B17,$C17*Z$5) -> 272.95145 | ... AD17: =IF($C17*AD$5>(5%*AD$5),(5%*AD$5)*$B17,$C17*AD$5) -> 268.43062 | AH17: =IF($C17*AH$5>(5%*AH$5),(5%*AH$5)*$B17,$C17*AH$5) -> 337.25628 | AI17: =IF($C17*AI$5>(5%*AI$5),(5%*AI$5)*$B17,$C17*AI$5) -> 335.68242 | AJ17: =IF($C17*AJ$5>(5%*AJ$5),(5%*AJ$5)*$B17,$C17*AJ$5) -> 334.1159 | AK17: =IF($C17*AK$5>(5%*AK$5),(5%*AK$5)*$B17,$C17*AK$5) -> 332.55669 | AL17: =IF($C17*AL$5>(5%*AL$5),(5%*AL$5)*$B17,$C17*AL$5) -> 331.00476 | AM17: =IF($C17*AM$5>(5%*AM$5),(5%*AM$5)*$B17,$C17*AM$5) -> 329.46007 | AN17: =IF($C17*AN$5>(5%*AN$5),(5%*AN$5)*$B17,$C17*AN$5) -> 327.92259 | AO17: =IF($C17*AO$5>(5%*AO$5),(5%*AO$5)*$B17,$C17*AO$5) -> 326.39229 | ... AS17: =IF($C17*AS$5>(5%*AS$5),(5%*AS$5)*$B17,$C17*AS$5) -> 320.34215 | AW17: =IF($C17*AW$5>(5%*AW$5),(5%*AW$5)*$B17,$C17*AW$5) -> 449.67504 | AX17: =IF($C17*AX$5>(5%*AX$5),(5%*AX$5)*$B17,$C17*AX$5) -> 447.12688 | AY17: =IF($C17*AY$5>(5%*AY$5),(5%*AY$5)*$B17,$C17*AY$5) -> 444.59316 | AZ17: =IF($C17*AZ$5>(5%*AZ$5),(5%*AZ$5)*$B17,$C17*AZ$5) -> 442.0738 | BA17: =IF($C17*BA$5>(5%*BA$5),(5%*BA$5)*$B17,$C17*BA$5) -> 439.56872 | BB17: =IF($C17*BB$5>(5%*BB$5),(5%*BB$5)*$B17,$C17*BB$5) -> 437.07783 | BC17: =IF($C17*BC$5>(5%*BC$5),(5%*BC$5)*$B17,$C17*BC$5) -> 434.60105 | BD17: =IF($C17*BD$5>(5%*BD$5),(5%*BD$5)*$B17,$C17*BD$5) -> 432.13831 | ... BH17: =IF($C17*BH$5>(5%*BH$5),(5%*BH$5)*$B17,$C17*BH$5) -> 422.42612 | BL17: =IF($C17*BL$5>(5%*BL$5),(5%*BL$5)*$B17,$C17*BL$5) -> 562.0938 | BM17: =IF($C17*BM$5>(5%*BM$5),(5%*BM$5)*$B17,$C17*BM$5) -> 558.34651 | BN17: =IF($C17*BN$5>(5%*BN$5),(5%*BN$5)*$B17,$C17*BN$5) -> 554.6242 | BO17: =IF($C17*BO$5>(5%*BO$5),(5%*BO$5)*$B17,$C17*BO$5) -> 550.9267 | BP17: =IF($C17*BP$5>(5%*BP$5),(5%*BP$5)*$B17,$C17*BP$5) -> 547.25386 | BQ17: =IF($C17*BQ$5>(5%*BQ$5),(5%*BQ$5)*$B17,$C17*BQ$5) -> 543.6055 | BR17: =IF($C17*BR$5>(5%*BR$5),(5%*BR$5)*$B17,$C17*BR$5) -> 539.98146 | BS17: =IF($C17*BS$5>(5%*BS$5),(5%*BS$5)*$B17,$C17*BS$5) -> 536.38159 | ... BW17: =IF($C17*BW$5>(5%*BW$5),(5%*BW$5)*$B17,$C17*BW$5) -> 522.22048
